Workbook

Sheet LED計算式
AD1: =VLOOKUP(代理店入力用!H5,AB5:AE12,1,FALSE) -> 10 | AE1: =VLOOKUP(代理店入力用!H5,AB5:AE12,4,FALSE) -> 0
F2: 12 | G2: 12 | H2: 12 | I2: 12 | J2: 12 | K2: 12 | L2: 12 | M2: 12 | N2: 12 | O2: 12 | T2: =SUM(T4:T33) -> 0 | U2: =SUM(U4:U33) -> 0 | AB2: 契約月数 | AC2: =VLOOKUP(代理店入力用!H5,AB5:AE12,2,FALSE) -> 0.0109 | AD2: =VLOOKUP(代理店入力用!H5,AB5:AE12,3,FALSE) -> 120 | AE2: =180-AD2 -> 60 | AI2: =SUM(AI4:AI33) -> 0 | AJ2: =SUM(AJ4:AJ33) -> 0 | AK2: =SUM(AK4:AK33) -> 0
B3: 10年間コスト | C3: 毎月 | E3: 0 | F3: 1 | G3: 2 | H3: 3 | I3: 4 | J3: 5 | K3: 6 | L3: 7 | M3: 8 | N3: 9 | O3: 10 | S3: 商品原価 | T3: 商品合計 | U3: 工事費 | V3: 売価 | AI3: 現状 | AJ3: LEDのみ | AK3: 電力も
B4: =②前a!AS41 -> 0 | C4: =ROUNDDOWN(B4/120,1) -> 0 | E4: 0 | F4: =ROUNDDOWN($C$4*F2*F3,0) -> 0 | G4: =ROUNDDOWN($C$4*G2*G3,0) -> 0 | H4: =ROUNDDOWN($C$4*H2*H3,0) -> 0 | I4: =ROUNDDOWN($C$4*I2*I3,0) -> 0 | J4: =ROUNDDOWN($C$4*J2*J3,0) -> 0 | K4: =ROUNDDOWN($C$4*K2*K3,0) -> 0 | L4: =ROUNDDOWN($C$4*L2*L3,0) -> 0 | M4: =ROUNDDOWN($C$4*M2*M3,0) -> 0 | ... O4: =ROUNDDOWN($C$4*O2*O3,0) -> 0 | Q4: 1 | S4: =IFERROR(VLOOKUP(☆入力!$G16,選定!$C$1:$AG$100,8,FALSE),"0") -> 0 | T4: =S4*☆入力!L16 -> 0 | U4: =☆入力!AE16*☆入力!L16 -> 0 | V4: =ROUNDDOWN((T4+U4),0) -> 0 | X4: =IFERROR((代理店入力用!$D$5/☆入力!$AH$14)*☆入力!$AH16,"0") -> 0 | Y4: =X4/54 -> 0 | AB4: リース期間/年 | AC4: 料率 | AD4: リース期間月数 | AH4: A | AI4: =ROUNDDOWN(☆入力!W16*☆入力!X16,0) -> 0 | AJ4: =ROUNDDOWN(☆入力!AB16*☆入力!X16,0) -> 0 | AK4: =ROUNDDOWN(☆入力!AB16*☆入力!AD16,0) -> 0
Q5: 2 | S5: =IFERROR(VLOOKUP(☆入力!$G17,選定!$C$1:$AG$100,8,FALSE),"0") -> 0 | T5: =S5*☆入力!L17 -> 0 | U5: =☆入力!AE17*☆入力!L17 -> 0 | V5: =ROUNDDOWN((T5+U5),0) -> 0 | X5: =IFERROR((代理店入力用!$D$5/☆入力!$AH$14)*☆入力!$AH17,"0") -> 0 | Y5: =X5/54 -> 0 | AB5: 3 | AC5: 0.0306 | AD5: 36 | AE5: 7 | AH5: B | AI5: =ROUNDDOWN(☆入力!W17*☆入力!X17,0) -> 0 | AJ5: =ROUNDDOWN(☆入力!AB17*☆入力!X17,0) -> 0 | AK5: =ROUNDDOWN(☆入力!AB17*☆入力!AD17,0) -> 0
E6: =(☆入力!$AL$14+代理店入力用!$D$5)*(100%-☆入力!$AR$11) -> 0 | F6: =(☆入力!$AL$14+代理店入力用!$D$5)*(100%-☆入力!$AR$11) -> 0 | G6: =(☆入力!$AL$14+代理店入力用!$D$5)*(100%-☆入力!$AR$11) -> 0 | H6: =(☆入力!$AL$14+代理店入力用!$D$5)*(100%-☆入力!$AR$11) -> 0 | I6: =(☆入力!$AL$14+代理店入力用!$D$5)*(100%-☆入力!$AR$11) -> 0 | J6: =(☆入力!$AL$14+代理店入力用!$D$5)*(100%-☆入力!$AR$11) -> 0 | K6: =(☆入力!$AL$14+代理店入力用!$D$5)*(100%-☆入力!$AR$11) -> 0 | L6: =(☆入力!$AL$14+代理店入力用!$D$5)*(100%-☆入力!$AR$11) -> 0 | ... O6: =(☆入力!$AL$14+代理店入力用!$D$5)*(100%-☆入力!$AR$11) -> 0 | Q6: 3 | S6: =IFERROR(VLOOKUP(☆入力!$G18,選定!$C$1:$AG$100,8,FALSE),"0") -> 0 | T6: =S6*☆入力!L18 -> 0 | U6: =☆入力!AE18*☆入力!L18 -> 0 | V6: =ROUNDDOWN((T6+U6),0) -> 0 | X6: =IFERROR((代理店入力用!$D$5/☆入力!$AH$14)*☆入力!$AH18,"0") -> 0 | Y6: =X6/54 -> 0 | AB6: 4 | AC6: 0.0231 | AD6: 48 | AE6: 6 | AH6: C | AI6: =ROUNDDOWN(☆入力!W18*☆入力!X18,0) -> 0 | AJ6: =ROUNDDOWN(☆入力!AB18*☆入力!X18,0) -> 0 | AK6: =ROUNDDOWN(☆入力!AB18*☆入力!AD18,0) -> 0
B7: =③後a!AS41 -> 0 | C7: =ROUNDDOWN(B7/120,1) -> 0 | E7: 0 | F7: =ROUNDDOWN($C$7*F2*F3,0) -> 0 | G7: =ROUNDDOWN($C$7*G2*G3,0) -> 0 | H7: =ROUNDDOWN($C$7*H2*H3,0) -> 0 | I7: =ROUNDDOWN($C$7*I2*I3,0) -> 0 | J7: =ROUNDDOWN($C$7*J2*J3,0) -> 0 | K7: =ROUNDDOWN($C$7*K2*K3,0) -> 0 | L7: =ROUNDDOWN($C$7*L2*L3,0) -> 0 | M7: =ROUNDDOWN($C$7*M2*M3,0) -> 0 | ... O7: =ROUNDDOWN($C$7*O2*O3,0) -> 0 | Q7: 4 | S7: =IFERROR(VLOOKUP(☆入力!$G19,選定!$C$1:$AG$100,8,FALSE),"0") -> 0 | T7: =S7*☆入力!L19 -> 0 | U7: =☆入力!AE19*☆入力!L19 -> 0 | V7: =ROUNDDOWN((T7+U7),0) -> 0 | X7: =IFERROR((代理店入力用!$D$5/☆入力!$AH$14)*☆入力!$AH19,"0") -> 0 | Y7: =X7/54 -> 0 | AB7: 5 | AC7: 0.0187 | AD7: 60 | AE7: 5 | AH7: D | AI7: =ROUNDDOWN(☆入力!W19*☆入力!X19,0) -> 0 | AJ7: =ROUNDDOWN(☆入力!AB19*☆入力!X19,0) -> 0 | AK7: =ROUNDDOWN(☆入力!AB19*☆入力!AD19,0) -> 0
E8: =E6+E7 -> 0 | F8: =F6+F7 -> 0 | G8: =G6+G7 -> 0 | H8: =H6+H7 -> 0 | I8: =I6+I7 -> 0 | J8: =J6+J7 -> 0 | K8: =K6+K7 -> 0 | L8: =L6+L7 -> 0 | ... O8: =O6+O7 -> 0 | Q8: 5 | S8: =IFERROR(VLOOKUP(☆入力!$G20,選定!$C$1:$AG$100,8,FALSE),"0") -> 0 | T8: =S8*☆入力!L20 -> 0 | U8: =☆入力!AE20*☆入力!L20 -> 0 | V8: =ROUNDDOWN((T8+U8),0) -> 0 | X8: =IFERROR((代理店入力用!$D$5/☆入力!$AH$14)*☆入力!$AH20,"0") -> 0 | Y8: =X8/54 -> 0 | AB8: 6 | AC8: 0.0159 | AD8: 72 | AE8: 4 | AH8: E | AI8: =ROUNDDOWN(☆入力!W20*☆入力!X20,0) -> 0 | AJ8: =ROUNDDOWN(☆入力!AB20*☆入力!X20,0) -> 0 | AK8: =ROUNDDOWN(☆入力!AB20*☆入力!AD20,0) -> 0
Q9: 6 | S9: =IFERROR(VLOOKUP(☆入力!$G21,選定!$C$1:$AG$100,8,FALSE),"0") -> 0 | T9: =S9*☆入力!L21 -> 0 | U9: =☆入力!AE21*☆入力!L21 -> 0 | V9: =ROUNDDOWN((T9+U9),0) -> 0 | X9: =IFERROR((代理店入力用!$D$5/☆入力!$AH$14)*☆入力!$AH21,"0") -> 0 | Y9: =X9/54 -> 0 | AB9: 7 | AC9: 0.0141 | AD9: 84 | AE9: 3 | AH9: F | AI9: =ROUNDDOWN(☆入力!W21*☆入力!X21,0) -> 0 | AJ9: =ROUNDDOWN(☆入力!AB21*☆入力!X21,0) -> 0 | AK9: =ROUNDDOWN(☆入力!AB21*☆入力!AD21,0) -> 0
Q10: 7 | S10: =IFERROR(VLOOKUP(☆入力!$G22,選定!$C$1:$AG$100,8,FALSE),"0") -> 0 | T10: =S10*☆入力!L22 -> 0 | U10: =☆入力!AE22*☆入力!L22 -> 0 | V10: =ROUNDDOWN((T10+U10),0) -> 0 | X10: =IFERROR((代理店入力用!$D$5/☆入力!$AH$14)*☆入力!$AH22,"0") -> 0 | Y10: =X10/54 -> 0 | AB10: 8 | AC10: 0.0127 | AD10: 96 | AE10: 2 | AH10: G | AI10: =ROUNDDOWN(☆入力!W22*☆入力!X22,0) -> 0 | AJ10: =ROUNDDOWN(☆入力!AB22*☆入力!X22,0) -> 0 | AK10: =ROUNDDOWN(☆入力!AB22*☆入力!AD22,0) -> 0
E11: =(☆入力!$AL$14+代理店入力用!$D$5)*(100%-☆入力!$AR$11-☆入力!$AR$12) -> 0 | F11: =(☆入力!$AL$14+代理店入力用!$D$5)*(100%-☆入力!$AR$11-☆入力!$AR$12) -> 0 | G11: =(☆入力!$AL$14+代理店入力用!$D$5)*(100%-☆入力!$AR$11-☆入力!$AR$12) -> 0 | H11: =(☆入力!$AL$14+代理店入力用!$D$5)*(100%-☆入力!$AR$11-☆入力!$AR$12) -> 0 | I11: =(☆入力!$AL$14+代理店入力用!$D$5)*(100%-☆入力!$AR$11-☆入力!$AR$12) -> 0 | J11: =(☆入力!$AL$14+代理店入力用!$D$5)*(100%-☆入力!$AR$11-☆入力!$AR$12) -> 0 | K11: =(☆入力!$AL$14+代理店入力用!$D$5)*(100%-☆入力!$AR$11-☆入力!$AR$12) -> 0 | L11: =(☆入力!$AL$14+代理店入力用!$D$5)*(100%-☆入力!$AR$11-☆入力!$AR$12) -> 0 | ... O11: =(☆入力!$AL$14+代理店入力用!$D$5)*(100%-☆入力!$AR$11-☆入力!$AR$12) -> 0 | Q11: 8 | S11: =IFERROR(VLOOKUP(☆入力!$G23,選定!$C$1:$AG$100,8,FALSE),"0") -> 0 | T11: =S11*☆入力!L23 -> 0 | U11: =☆入力!AE23*☆入力!L23 -> 0 | V11: =ROUNDDOWN((T11+U11),0) -> 0 | X11: =IFERROR((代理店入力用!$D$5/☆入力!$AH$14)*☆入力!$AH23,"0") -> 0 | Y11: =X11/54 -> 0 | AB11: 9 | AC11: 0.0117 | AD11: 108 | AE11: 1 | AH11: H | AI11: =ROUNDDOWN(☆入力!W23*☆入力!X23,0) -> 0 | AJ11: =ROUNDDOWN(☆入力!AB23*☆入力!X23,0) -> 0 | AK11: =ROUNDDOWN(☆入力!AB23*☆入力!AD23,0) -> 0
B12: =B7 -> 0 | C12: =ROUNDDOWN(B12/120,1) -> 0 | E12: 0 | F12: =ROUNDDOWN($C$12*F2*F3,0) -> 0 | G12: =ROUNDDOWN($C$12*G2*G3,0) -> 0 | H12: =ROUNDDOWN($C$12*H2*H3,0) -> 0 | I12: =ROUNDDOWN($C$12*I2*I3,0) -> 0 | J12: =ROUNDDOWN($C$12*J2*J3,0) -> 0 | K12: =ROUNDDOWN($C$12*K2*K3,0) -> 0 | L12: =ROUNDDOWN($C$12*L2*L3,0) -> 0 | M12: =ROUNDDOWN($C$12*M2*M3,0) -> 0 | ... O12: =ROUNDDOWN($C$12*O2*O3,0) -> 0 | Q12: 9 | S12: =IFERROR(VLOOKUP(☆入力!$G24,選定!$C$1:$AG$100,8,FALSE),"0") -> 0 | T12: =S12*☆入力!L24 -> 0 | U12: =☆入力!AE24*☆入力!L24 -> 0 | V12: =ROUNDDOWN((T12+U12),0) -> 0 | X12: =IFERROR((代理店入力用!$D$5/☆入力!$AH$14)*☆入力!$AH24,"0") -> 0 | Y12: =X12/54 -> 0 | AB12: 10 | AC12: 0.0109 | AD12: 120 | AE12: 0 | AH12: I | AI12: =ROUNDDOWN(☆入力!W24*☆入力!X24,0) -> 0 | AJ12: =ROUNDDOWN(☆入力!AB24*☆入力!X24,0) -> 0 | AK12: =ROUNDDOWN(☆入力!AB24*☆入力!AD24,0) -> 0
E13: =E11+E12 -> 0 | F13: =F11+F12 -> 0 | G13: =G11+G12 -> 0 | H13: =H11+H12 -> 0 | I13: =I11+I12 -> 0 | J13: =J11+J12 -> 0 | K13: =K11+K12 -> 0 | L13: =L11+L12 -> 0 | ... O13: =O11+O12 -> 0 | Q13: 10 | S13: =IFERROR(VLOOKUP(☆入力!$G25,選定!$C$1:$AG$100,8,FALSE),"0") -> 0 | T13: =S13*☆入力!L25 -> 0 | U13: =☆入力!AE25*☆入力!L25 -> 0 | V13: =ROUNDDOWN((T13+U13),0) -> 0 | X13: =IFERROR((代理店入力用!$D$5/☆入力!$AH$14)*☆入力!$AH25,"0") -> 0 | Y13: =X13/54 -> 0 | AH13: J | AI13: =ROUNDDOWN(☆入力!W25*☆入力!X25,0) -> 0 | AJ13: =ROUNDDOWN(☆入力!AB25*☆入力!X25,0) -> 0 | AK13: =ROUNDDOWN(☆入力!AB25*☆入力!AD25,0) -> 0
Q14: 11 | S14: =IFERROR(VLOOKUP(☆入力!$G26,選定!$C$1:$AG$100,8,FALSE),"0") -> 0 | T14: =S14*☆入力!L26 -> 0 | U14: =☆入力!AE26*☆入力!L26 -> 0 | V14: =ROUNDDOWN((T14+U14),0) -> 0 | X14: =IFERROR((代理店入力用!$D$5/☆入力!$AH$14)*☆入力!$AH26,"0") -> 0 | Y14: =X14/54 -> 0 | AH14: K | AI14: =ROUNDDOWN(☆入力!W26*☆入力!X26,0) -> 0 | AJ14: =ROUNDDOWN(☆入力!AB26*☆入力!X26,0) -> 0 | AK14: =ROUNDDOWN(☆入力!AB26*☆入力!AD26,0) -> 0
Q15: 12 | S15: =IFERROR(VLOOKUP(☆入力!$G27,選定!$C$1:$AG$100,8,FALSE),"0") -> 0 | T15: =S15*☆入力!L27 -> 0 | U15: =☆入力!AE27*☆入力!L27 -> 0 | V15: =ROUNDDOWN((T15+U15),0) -> 0 | X15: =IFERROR((代理店入力用!$D$5/☆入力!$AH$14)*☆入力!$AH27,"0") -> 0 | Y15: =X15/54 -> 0 | AH15: L | AI15: =ROUNDDOWN(☆入力!W27*☆入力!X27,0) -> 0 | AJ15: =ROUNDDOWN(☆入力!AB27*☆入力!X27,0) -> 0 | AK15: =ROUNDDOWN(☆入力!AB27*☆入力!AD27,0) -> 0
C16: 現状 | D16: 5年間 | E16: 6年目以降 | H16: ⑥非なし | I16: ⑥非あり | M16: 360 | N16: =SUMIF(☆入力!H16:H40,360,☆入力!L16:L40) -> 0 | Q16: 13 | S16: =IFERROR(VLOOKUP(☆入力!$G28,選定!$C$1:$AG$100,8,FALSE),"0") -> 0 | T16: =S16*☆入力!L28 -> 0 | U16: =☆入力!AE28*☆入力!L28 -> 0 | V16: =ROUNDDOWN((T16+U16),0) -> 0 | X16: =IFERROR((代理店入力用!$D$5/☆入力!$AH$14)*☆入力!$AH28,"0") -> 0 | Y16: =X16/54 -> 0 | AH16: M | AI16: =ROUNDDOWN(☆入力!W28*☆入力!X28,0) -> 0 | AJ16: =ROUNDDOWN(☆入力!AB28*☆入力!X28,0) -> 0 | AK16: =ROUNDDOWN(☆入力!AB28*☆入力!AD28,0) -> 0
B17: B | M17: 720 | N17: =SUMIF(☆入力!H16:H40,720,☆入力!L16:L40) -> 0 | Q17: 14 | S17: =IFERROR(VLOOKUP(☆入力!$G29,選定!$C$1:$AG$100,8,FALSE),"0") -> 0 | T17: =S17*☆入力!L29 -> 0 | U17: =☆入力!AE29*☆入力!L29 -> 0 | V17: =ROUNDDOWN((T17+U17),0) -> 0 | X17: =IFERROR((代理店入力用!$D$5/☆入力!$AH$14)*☆入力!$AH29,"0") -> 0 | Y17: =X17/54 -> 0 | AH17: N | AI17: =ROUNDDOWN(☆入力!W29*☆入力!X29,0) -> 0 | AJ17: =ROUNDDOWN(☆入力!AB29*☆入力!X29,0) -> 0 | AK17: =ROUNDDOWN(☆入力!AB29*☆入力!AD29,0) -> 0
B18: バイパス | H18: 削減金額 | Q18: 15 | S18: =IFERROR(VLOOKUP(☆入力!$G30,選定!$C$1:$AG$100,8,FALSE),"0") -> 0 | T18: =S18*☆入力!L30 -> 0 | U18: =☆入力!AE30*☆入力!L30 -> 0 | V18: =ROUNDDOWN((T18+U18),0) -> 0 | X18: =IFERROR((代理店入力用!$D$5/☆入力!$AH$14)*☆入力!$AH30,"0") -> 0 | Y18: =X18/54 -> 0 | AH18: O | AI18: =ROUNDDOWN(☆入力!W30*☆入力!X30,0) -> 0 | AJ18: =ROUNDDOWN(☆入力!AB30*☆入力!X30,0) -> 0 | AK18: =ROUNDDOWN(☆入力!AB30*☆入力!AD30,0) -> 0
B19: 削減金額 | H19: リース代 | J19: =⑧見積書!J10 -> 0 | Q19: 16 | S19: =IFERROR(VLOOKUP(☆入力!$G31,選定!$C$1:$AG$100,8,FALSE),"0") -> 0 | T19: =S19*☆入力!L31 -> 0 | U19: =☆入力!AE31*☆入力!L31 -> 0 | V19: =ROUNDDOWN((T19+U19),0) -> 0 | X19: =IFERROR((代理店入力用!$D$5/☆入力!$AH$14)*☆入力!$AH31,"0") -> 0 | Y19: =X19/54 -> 0 | AH19: P | AI19: =ROUNDDOWN(☆入力!W31*☆入力!X31,0) -> 0 | AJ19: =ROUNDDOWN(☆入力!AB31*☆入力!X31,0) -> 0 | AK19: =ROUNDDOWN(☆入力!AB31*☆入力!AD31,0) -> 0
B20: リース代 | D20: =ROUNDDOWN(LED計算式!#REF!,1) -> #REF! | H20: 交換コスト | I20: =ROUNDDOWN((②前a!AS13+②前a!AS24)/120,0) -> 0 | J20: =ROUNDDOWN((③後a!AS13+③後a!AS24)/120,0) -> 0 | K20: =ROUNDDOWN((③後a!AS13+③後a!AS24)/120,0) -> 0 | M20: 電球数 | N20: 人工 | Q20: 17 | S20: =IFERROR(VLOOKUP(☆入力!$G32,選定!$C$1:$AG$100,8,FALSE),"0") -> 0 | T20: =S20*☆入力!L32 -> 0 | U20: =☆入力!AE32*☆入力!L32 -> 0 | V20: =ROUNDDOWN((T20+U20),0) -> 0 | X20: =IFERROR((代理店入力用!$D$5/☆入力!$AH$14)*☆入力!$AH32,"0") -> 0 | Y20: =X20/54 -> 0 | AH20: Q | AI20: =ROUNDDOWN(☆入力!W32*☆入力!X32,0) -> 0 | AJ20: =ROUNDDOWN(☆入力!AB32*☆入力!X32,0) -> 0 | AK20: =ROUNDDOWN(☆入力!AB32*☆入力!AD32,0) -> 0
B21: 電気代 | C21: =ROUNDDOWN(☆入力!Y14,1) -> 0 | D21: =ROUNDDOWN(☆入力!AC14,1) -> 0 | E21: =ROUNDDOWN(☆入力!AC14,1) -> 0 | H21: 電気代 | I21: =ROUNDDOWN(C21,0) -> 0 | J21: =ROUNDDOWN(D21,0) -> 0 | K21: =ROUNDDOWN(E21,0) -> 0 | M21: 0 | N21: 1 | Q21: 18 | S21: =IFERROR(VLOOKUP(☆入力!$G33,選定!$C$1:$AG$100,8,FALSE),"0") -> 0 | T21: =S21*☆入力!L33 -> 0 | U21: =☆入力!AE33*☆入力!L33 -> 0 | V21: =ROUNDDOWN((T21+U21),0) -> 0 | X21: =IFERROR((代理店入力用!$D$5/☆入力!$AH$14)*☆入力!$AH33,"0") -> 0 | Y21: =X21/54 -> 0 | AH21: R | AI21: =ROUNDDOWN(☆入力!W33*☆入力!X33,0) -> 0 | AJ21: =ROUNDDOWN(☆入力!AB33*☆入力!X33,0) -> 0 | AK21: =ROUNDDOWN(☆入力!AB33*☆入力!AD33,0) -> 0
B22: 合計 | C22: =SUM(C19:C21) -> 0 | D22: =SUM(D19:D21) -> #REF! | E22: =SUM(E19:E21) -> 0 | H22: 合計 | I22: =SUM(I20:I21) -> 0 | J22: =SUM(J19:J21) -> 0 | K22: =SUM(K19:K21) -> 0 | M22: 21 | N22: 2 | Q22: 19 | S22: =IFERROR(VLOOKUP(☆入力!$G34,選定!$C$1:$AG$100,8,FALSE),"0") -> 0 | T22: =S22*☆入力!L34 -> 0 | U22: =☆入力!AE34*☆入力!L34 -> 0 | V22: =ROUNDDOWN((T22+U22),0) -> 0 | X22: =IFERROR((代理店入力用!$D$5/☆入力!$AH$14)*☆入力!$AH34,"0") -> 0 | Y22: =X22/54 -> 0 | AH22: S | AI22: =ROUNDDOWN(☆入力!W34*☆入力!X34,0) -> 0 | AJ22: =ROUNDDOWN(☆入力!AB34*☆入力!X34,0) -> 0 | AK22: =ROUNDDOWN(☆入力!AB34*☆入力!AD34,0) -> 0
D23: =C22-D22 -> #REF! | E23: =C22-E22 -> 0 | J23: =INT(I22-J22) -> 0 | K23: =INT(I22-K22) -> 0 | M23: 41 | N23: 3 | Q23: 20 | S23: =IFERROR(VLOOKUP(☆入力!$G35,選定!$C$1:$AG$100,8,FALSE),"0") -> 0 | T23: =S23*☆入力!L35 -> 0 | U23: =☆入力!AE35*☆入力!L35 -> 0 | V23: =ROUNDDOWN((T23+U23),0) -> 0 | X23: =IFERROR((代理店入力用!$D$5/☆入力!$AH$14)*☆入力!$AH35,"0") -> 0 | Y23: =X23/54 -> 0 | AH23: T | AI23: =ROUNDDOWN(☆入力!W35*☆入力!X35,0) -> 0 | AJ23: =ROUNDDOWN(☆入力!AB35*☆入力!X35,0) -> 0 | AK23: =ROUNDDOWN(☆入力!AB35*☆入力!AD35,0) -> 0
D24: =100%-(D22/C22) -> #REF! | E24: =100%-(E22/C22) -> #DIV/0! | J24: =100%-(J22/I22) -> #DIV/0! | K24: =100%-(K22/I22) -> #DIV/0! | M24: 61 | N24: 4 | Q24: 21 | S24: =IFERROR(VLOOKUP(☆入力!$G36,選定!$C$1:$AG$100,8,FALSE),"0") -> 0 | T24: =S24*☆入力!L36 -> 0 | U24: =☆入力!AE36*☆入力!L36 -> 0 | V24: =ROUNDDOWN((T24+U24),0) -> 0 | X24: =IFERROR((代理店入力用!$D$5/☆入力!$AH$14)*☆入力!$AH36,"0") -> 0 | Y24: =X24/54 -> 0 | AH24: U | AI24: =ROUNDDOWN(☆入力!W36*☆入力!X36,0) -> 0 | AJ24: =ROUNDDOWN(☆入力!AB36*☆入力!X36,0) -> 0 | AK24: =ROUNDDOWN(☆入力!AB36*☆入力!AD36,0) -> 0
D25: =-(C22-D22) -> #REF! | J25: =-(I22-J22) -> 0 | M25: 81 | N25: 5 | Q25: 22 | S25: =IFERROR(VLOOKUP(☆入力!$G37,選定!$C$1:$AG$100,8,FALSE),"0") -> 0 | T25: =S25*☆入力!L37 -> 0 | U25: =☆入力!AE37*☆入力!L37 -> 0 | V25: =ROUNDDOWN((T25+U25),0) -> 0 | X25: =IFERROR((代理店入力用!$D$5/☆入力!$AH$14)*☆入力!$AH37,"0") -> 0 | Y25: =X25/54 -> 0 | AH25: V | AI25: =ROUNDDOWN(☆入力!W37*☆入力!X37,0) -> 0 | AJ25: =ROUNDDOWN(☆入力!AB37*☆入力!X37,0) -> 0 | AK25: =ROUNDDOWN(☆入力!AB37*☆入力!AD37,0) -> 0
M26: 100 | N26: 6 | Q26: 23 | S26: =IFERROR(VLOOKUP(☆入力!$G38,選定!$C$1:$AG$100,8,FALSE),"0") -> 0 | T26: =S26*☆入力!L38 -> 0 | U26: =☆入力!AE38*☆入力!L38 -> 0 | V26: =ROUNDDOWN((T26+U26),0) -> 0 | X26: =IFERROR((代理店入力用!$D$5/☆入力!$AH$14)*☆入力!$AH38,"0") -> 0 | Y26: =X26/54 -> 0 | AH26: W | AI26: =ROUNDDOWN(☆入力!W38*☆入力!X38,0) -> 0 | AJ26: =ROUNDDOWN(☆入力!AB38*☆入力!X38,0) -> 0 | AK26: =ROUNDDOWN(☆入力!AB38*☆入力!AD38,0) -> 0
M27: 1000 | N27: 50 | Q27: 24 | S27: =IFERROR(VLOOKUP(☆入力!$G39,選定!$C$1:$AG$100,8,FALSE),"0") -> 0 | T27: =S27*☆入力!L39 -> 0 | U27: =☆入力!AE39*☆入力!L39 -> 0 | V27: =ROUNDDOWN((T27+U27),0) -> 0 | X27: =IFERROR((代理店入力用!$D$5/☆入力!$AH$14)*☆入力!$AH39,"0") -> 0 | Y27: =X27/54 -> 0 | AH27: Z | AI27: =ROUNDDOWN(☆入力!W39*☆入力!X39,0) -> 0 | AJ27: =ROUNDDOWN(☆入力!AB39*☆入力!X39,0) -> 0 | AK27: =ROUNDDOWN(☆入力!AB39*☆入力!AD39,0) -> 0
Q28: 25 | S28: =IFERROR(VLOOKUP(☆入力!$G40,選定!$C$1:$AG$100,8,FALSE),"0") -> 0 | T28: =S28*☆入力!L40 -> 0 | U28: =☆入力!AE40*☆入力!L40 -> 0 | V28: =ROUNDDOWN((T28+U28),0) -> 0 | X28: =IFERROR((代理店入力用!$D$5/☆入力!$AH$14)*☆入力!$AH40,"0") -> 0 | Y28: =X28/54 -> 0 | AH28: Y | AI28: =ROUNDDOWN(☆入力!W40*☆入力!X40,0) -> 0 | AJ28: =ROUNDDOWN(☆入力!AB40*☆入力!X40,0) -> 0 | AK28: =ROUNDDOWN(☆入力!AB40*☆入力!AD40,0) -> 0
D29: =100%-(③後a!AS6/②前a!AS6) -> #DIV/0! | H29: ⑦非なし | I29: ⑦非あり | Q29: 26 | S29: =IFERROR(VLOOKUP(☆入力!$G41,選定!$C$1:$AG$100,8,FALSE),"0") -> 0 | T29: =S29*☆入力!L41 -> 0 | U29: =☆入力!AE41*☆入力!L41 -> 0 | V29: =ROUNDDOWN((T29+U29),0) -> 0 | X29: =IFERROR((代理店入力用!$D$5/☆入力!$AH$14)*☆入力!$AH41,"0") -> 0 | Y29: =X29/54 -> 0 | AH29: Z | AI29: =ROUNDDOWN(☆入力!W41*☆入力!X41,0) -> 0 | AJ29: =ROUNDDOWN(☆入力!AB41*☆入力!X41,0) -> 0 | AK29: =ROUNDDOWN(☆入力!AB41*☆入力!AD41,0) -> 0
Q30: 27 | S30: =IFERROR(VLOOKUP(☆入力!$G42,選定!$C$1:$AG$100,8,FALSE),"0") -> 0 | T30: =S30*☆入力!L42 -> 0 | U30: =☆入力!AE42*☆入力!L42 -> 0 | V30: =ROUNDDOWN((T30+U30),0) -> 0 | X30: =IFERROR((代理店入力用!$D$5/☆入力!$AH$14)*☆入力!$AH42,"0") -> 0 | Y30: =X30/54 -> 0 | AH30: AA | AI30: =ROUNDDOWN(☆入力!W42*☆入力!X42,0) -> 0 | AJ30: =ROUNDDOWN(☆入力!AB42*☆入力!X42,0) -> 0 | AK30: =ROUNDDOWN(☆入力!AB42*☆入力!AD42,0) -> 0
D31: =②前a!AS41-③後a!AS41 -> 0 | H31: 削減金額 | Q31: 28 | S31: =IFERROR(VLOOKUP(☆入力!$G43,選定!$C$1:$AG$100,8,FALSE),"0") -> 0 | T31: =S31*☆入力!L43 -> 0 | U31: =☆入力!AE43*☆入力!L43 -> 0 | V31: =ROUNDDOWN((T31+U31),0) -> 0 | X31: =IFERROR((代理店入力用!$D$5/☆入力!$AH$14)*☆入力!$AH43,"0") -> 0 | Y31: =X31/54 -> 0 | AH31: AB | AI31: =ROUNDDOWN(☆入力!W43*☆入力!X43,0) -> 0 | AJ31: =ROUNDDOWN(☆入力!AB43*☆入力!X43,0) -> 0 | AK31: =ROUNDDOWN(☆入力!AB43*☆入力!AD43,0) -> 0
B32: =ROUNDDOWN((☆入力!AL14)*(100%-☆入力!AR11)+代理店入力用!D5,0) -> 0 | H32: リース代 | J32: ='⑧-bｼﾐｭ'!R7 -> 0 | M32: =VLOOKUP(☆入力!B14,N32:O33,2,) -> 試算エリア | N32: 1棟のみ | O32: 試算エリア | Q32: 29 | S32: =IFERROR(VLOOKUP(☆入力!$G44,選定!$C$1:$AG$100,8,FALSE),"0") -> 0 | T32: =S32*☆入力!L44 -> 0 | U32: =☆入力!AE44*☆入力!L44 -> 0 | V32: =ROUNDDOWN((T32+U32),0) -> 0 | X32: =IFERROR((代理店入力用!$D$5/☆入力!$AH$14)*☆入力!$AH44,"0") -> 0 | Y32: =X32/54 -> 0 | AH32: AC | AI32: =ROUNDDOWN(☆入力!W44*☆入力!X44,0) -> 0 | AJ32: =ROUNDDOWN(☆入力!AB44*☆入力!X44,0) -> 0 | AK32: =ROUNDDOWN(☆入力!AB44*☆入力!AD44,0) -> 0
B33: =(B32/(100%-☆入力!AR11))*(100%-☆入力!AR11-☆入力!AR12) -> 0 | D33: =☆入力!AR11 -> 0 | H33: 交換コスト | I33: =I20 -> 0 | J33: =J20 -> 0 | K33: =K20 -> 0 | N33: 複数棟 | O33: 物件名 | Q33: 30 | S33: =IFERROR(VLOOKUP(☆入力!$G45,選定!$C$1:$AG$100,8,FALSE),"0") -> 0 | T33: =S33*☆入力!L45 -> 0 | U33: =☆入力!AE45*☆入力!L45 -> 0 | V33: =ROUNDDOWN((T33+U33),0) -> 0 | X33: =IFERROR((代理店入力用!$D$5/☆入力!$AH$14)*☆入力!$AH45,"0") -> 0 | Y33: =X33/54 -> 0 | AH33: AD | AI33: =ROUNDDOWN(☆入力!W45*☆入力!X45,0) -> 0 | AJ33: =ROUNDDOWN(☆入力!AB45*☆入力!X45,0) -> 0 | AK33: =ROUNDDOWN(☆入力!AB45*☆入力!AD45,0) -> 0
H34: 電気代 | I34: =I21 -> 0 | J34: =J21 -> 0 | K34: =K21 -> 0
H35: 合計 | I35: =SUM(I32:I34) -> 0 | J35: =SUM(J32:J34) -> 0 | K35: =SUM(K32:K34) -> 0
C36: 特殊工事 | J36: =INT(I35-J35) -> 0 | K36: =INT(I35-K35) -> 0 | M36: 通常施工 | N36: 3000 | O36: =SUMIFS(☆入力!$L$16:$L$45,☆入力!$AE$16:$AE$45,N36) -> 0
C37: 高所作業費用 | M37: 非常灯別置 | N37: 5000 | O37: =SUMIFS(☆入力!$L$16:$L$45,☆入力!$AE$16:$AE$45,N37) -> 0
C38: 庭園灯作業 | M38: 配線直結 | O38: =SUMIFS(☆入力!$L$16:$L$45,☆入力!$AE$16:$AE$45,N38) -> 0
C39: 新設配線費用 | M39: ランプ交換 | O39: =SUMIFS(☆入力!$L$16:$L$45,☆入力!$AE$16:$AE$45,N39) -> 0
C40: EEセンサー交換費用
...

Sheet 選定
A1: 写真① | B1: 写真② | C1: 電球種別 | D1: 照明色 | E1: 器具色 | F1: 器具サイズ （設置面） | G1: 消費 電力 | H1: 全光束 | I1: 合算 定価 | J1: 合算 仕入 | K1: 防滴 | L1: 電球種別 | M1: メーカー | N1: W相当 | O1: 器具型番 | P1: 定価 | Q1: 仕入れ | R1: 型番② | S1: 定価② | T1: 仕入② | U1: 型番③ | V1: 定価③ | W1: 仕入③ | X1: 型番④ | Y1: 定価③ | Z1: 仕入③ | AA1: 消費電力 | AB1: 全光束 | AC1: 器具素材 | AD1: 器具色 選択肢 | AE1: 照明色 選択肢 | AF1: 定格 寿命 | AG1: 交換 方法 | AH1: 口金 | AI1: HP | AJ1: 備考
A2: 0 | B2: 0 | C2: 1 | D2: 2 | E2: 3 | F2: 4 | G2: 5 | H2: 6 | I2: 7 | J2: 8 | K2: 9 | L2: 10 | M2: 11 | N2: 12 | O2: 13 | P2: 14 | Q2: 15 | R2: 16 | S2: 17 | T2: 18 | U2: 19 | V2: 20 | W2: 21 | X2: 22 | Y2: 23 | Z2: 24 | AA2: 25 | AB2: 26 | AC2: 27 | AD2: 28 | AE2: 29 | AF2: 30 | AG2: 31 | AH2: 32 | AI2: 33 | AJ2: 34
C7: ************************
C8: ************************
C9: ************************
C10: ************************
C11: ************************
C12: ************************
C13: ************************
C14: ************************
C15: ************************
C16: ************************
C17: ************************
C18: ************************
... C40: ************************

Sheet ☆入力
B1: 受注額 | C1: 仕入額 | D1: 粗利益 | E1: リース代 | F1: 紹介料 | G1: 紹介斡旋料 | I1: ↓ここに数量表を貼り付け | X1: ↓「備考」・・・シート【前後】の『備考』へ反映
B2: =AO14 -> 0 | C2: =AP14 -> 0 | D2: =AQ14 -> 0 | E2: =AR14 -> 0 | F2: =AS14 -> 0 | G2: =AT14 -> 0 | M2: 【安定器が存在する電球は、全て「＋2W」で計上】 | AH2: ↓下記への入力は見積書に反映、
A3: ※電力を付帯しない場合には、電力割引を0%に変更してください | AH3: 備考(LED済みの箇所などを記載)：
M4: ↓安定器がある照明リスト | AH4: 生産終了品などがあった場合、同メーカーもしくは他メーカーの同等品に変更される場合がございます。
A5: 物件名： | M5: 直管蛍光灯（FL） | AH5: 新しい照明器具が、既設よりも一回り小さくなるケースがあり、その際は外壁塗装面が露出する
A6: 物件住所： | M6: サークライン（FCL） | AH6: 可能性がございます。
A7: 解錠番号： | M7: コンパクト蛍光灯（FDL、FHT、FPL、FML）
A8: 分電盤場所： | M8: ※水銀灯も安定器が存在するが、例外としてそのまま計上 | AR8: ※代理店案件の場合には、「代理店入力シート」にて金額変更
A9: 【工事依頼特記事項】 | M9: （例）20形蛍光灯・・・20W→22W | AQ9: 電球交換費 | AR9: =代理店入力用!D8 -> 0
AL10: 合計
M11: ① | N11: ② | O11: ③ | P11: ④ | Q11: ※複数棟合算の場合は | AH11: 【特殊工事】 | AJ11: 金額 | AL11: 1球売価 | AM11: 1球粗利 | AN11: 回収期間 | AQ11: 複数棟割引： | AS11: 紹介料：
J12: 非常灯・誘導灯の数→ | L12: =SUM(M12:P12) -> 0 | Q12: 個別に非常灯の数を入力 | AL12: =IFERROR(AO14/AH14,"0") -> 0 | AM12: =IFERROR(AQ14/AH14,"0") -> 0 | AN12: =⑨シミュレーション!AQ32 -> 0 | AQ12: 電力割引： | AR12: 0.05 | AS12: 斡旋料： | AT12: 0.03
AY13: 工事依頼・完了報告書
B14: 1棟のみ | C14: ←選択する | G14: ※選択制 | L14: =SUM(L16:L45) -> 0 | W14: =SUM(W16:W45) -> 0 | Y14: =SUM(Y16:Y45) -> 0 | AB14: =SUM(AB16:AB45) -> 0 | AC14: =SUM(AC16:AC45) -> 0 | AE14: ※手打可能 | AH14: =SUM(AH16:AH45) -> 0 | AI14: =SUM(AI16:AI45) -> 0 | AJ14: =SUM(AJ16:AJ45)+AJ12 -> 0 | AK14: =AL14/54 -> 0 | AL14: =SUM(AL16:AL45)+AJ12 -> 0 | AM14: =SUM(AM16:AM45) -> 0 | AO14: =SUM(AO16:AO45) -> 0 | AP14: =SUM(AP16:AP45) -> 0 | AQ14: =SUM(AQ16:AQ45) -> 0 | AR14: =SUM(AR16:AR45) -> 0 | AS14: =SUM(AS16:AS45) -> 0 | AT14: =SUM(AT16:AT45) -> 0 | AU14: ↓【5％】選択
B15: 物件名 | C15: 試算エリア | D15: 照明種別 | E15: 現調備考 | F15: 工事備考 | G15: 器具分類② | H15: 月間点灯 | I15: 一日点灯 | J15: 稼働日数 | K15: 消費電力 | L15: 電球数 | M15: 1階 | N15: 2階 | O15: 3階 | P15: 4階 | Q15: 5階 | R15: 6階 | S15: 7階 | T15: 8階 | U15: 9階 | V15: 10階 | W15: kWh | X15: 現状電気単価 | Y15: 電気代 | Z15: ⇒ | AA15: 消費電力 | AB15: kWh | AC15: 電気代 | AD15: 変更電気単価 | AE15: 工事単価 | AG15: 物件名 | AH15: 数量 | AI15: 商品原価 | AJ15: 工事費 | AK15: リース代 | AL15: 一括売価 | AM15: 粗利予測 | AN15: 利益率 | AO15: 受注額 | AP15: 仕入額 | AQ15: 粗利益 | AR15: 月額リース料 | AS15: 紹介料 | AT15: 紹介斡旋料 | AU15: 新電力割引 | AV15: 1球売価 | AW15: 1球粗利 | AY15: 交換方法 | AZ15: 試算エリア | BA15: 既存照明種別 | BB15: メーカー | BC15: 器具型番 | BD15: 器具型番② | BE15: 器具型番③ | BF15: 器具型番④ | BG15: 数量
A16: A | B16: =IF(C16="","",$C$5) | H16: =PRODUCT(I16,J16) -> 0 | J16: =IF(I16<>"",30,"") | L16: =SUM(M16:V16) -> 0 | W16: =($L16*$K16*$H16)/1000 -> 0 | X16: 30 | Y16: =ROUNDDOWN($W16*$X16,0) -> 0 | AA16: =IFERROR(VLOOKUP($G16,選定!$C$3:$AG$100,5,FALSE),0) -> 0 | AB16: =($AA16*$L16*$H16)/1000 -> 0 | AC16: =ROUNDDOWN($AB16*$AD16,0) -> 0 | AD16: 30 | AE16: 3000 | AF16: 1 | AG16: =C5 -> 0 | AH16: =SUMIF($B$16:$B$45,$AG16,$L$16:$L$45) -> 0 | AI16: =SUMIF($B$16:$B$45,$AG16,LED計算式!$T$4:$T$33) -> 0 | AJ16: =SUMIF($B$16:$B$45,$AG16,LED計算式!$U$4) -> 0 | AK16: =IFERROR(AL16*LED計算式!$AC$2,"") -> 0 | AL16: =ROUNDDOWN((AI16+AJ16)/(100%-$AN16),-3) -> 0 | AM16: =IFERROR($AL16-$AI16-$AJ16,"") -> 0 | AN16: 0.4 | AO16: =IFERROR(ROUNDDOWN($AL16*(100%-($AR$11+AU16)),-3),"") -> 0 | AP16: =AI16+AJ16 -> 0 | AQ16: =IFERROR(AO16-AI16-AJ16-AS16-AT16,"") -> 0 | AR16: =ROUNDDOWN(AO16*LED計算式!$AC$2,0) -> 0 | AS16: =IFERROR(AO16*$AT$11,"") -> 0 | AT16: =AO16*$AT$12 -> 0 | AV16: =IFERROR(AO16/AH16,0) -> 0 | AW16: =IFERROR(AQ16/AH16,0) -> 0 | AY16: =IFERROR(VLOOKUP(G16,選定!$C$3:$AG$100,28,FALSE),"0") -> 0 | AZ16: =C16 -> 0 | BA16: =D16 -> 0 | BB16: =IFERROR(VLOOKUP(G16,選定!$C$2:$AG$100,11,FALSE),"0") -> 0 | BC16: =IFERROR(VLOOKUP(G16,選定!$C$2:$AG$100,13,FALSE),"") | BD16: =IFERROR(VLOOKUP(G16,選定!$C$2:$AG$100,16,FALSE),"") | BE16: =IFERROR(VLOOKUP(G16,選定!$C$2:$AG$100,19,FALSE),"") | BF16: =IFERROR(VLOOKUP(G16,選定!$C$2:$AG$100,22,FALSE),"") | BG16: =L16 -> 0
A17: B | B17: =IF(C17="","",$C$5) | H17: =PRODUCT(I17,J17) -> 0 | J17: =IF(I17<>"",30,"") | L17: =SUM(M17:V17) -> 0 | W17: =($L17*$K17*$H17)/1000 -> 0 | X17: =$X$16 -> 30 | Y17: =ROUNDDOWN($W17*$X17,0) -> 0 | AA17: =IFERROR(VLOOKUP($G17,選定!$C$3:$AG$100,5,FALSE),0) -> 0 | AB17: =($AA17*$L17*$H17)/1000 -> 0 | AC17: =ROUNDDOWN($AB17*$AD17,0) -> 0 | AD17: =$AD$16 -> 30 | AE17: 3000 | AF17: 2 | AH17: =SUMIF($B$16:$B$45,$AG17,$L$16:$L$45) -> 0 | AI17: =SUMIF($B$16:$B$45,$AG17,LED計算式!$T$4:$T$33) -> 0 | AJ17: =SUMIF($B$16:$B$45,$AG17,LED計算式!$U$4) -> 0 | AK17: =IFERROR(AL17*LED計算式!$AC$2,"") -> 0 | AL17: =ROUNDDOWN((AI17+AJ17)/(100%-$AN17),-3) -> 0 | AM17: =IFERROR($AL17-$AI17-$AJ17,"") -> 0 | AN17: =$AN$16 -> 0.4 | AO17: =IFERROR(ROUNDDOWN($AL17*(100%-($AR$11+AU17)),-3),"") -> 0 | AP17: =AI17+AJ17 -> 0 | AQ17: =IFERROR(AO17-AI17-AJ17-AS17-AT17,"") -> 0 | AR17: =ROUNDDOWN(AO17*LED計算式!$AC$2,0) -> 0 | AS17: =IFERROR(AO17*$AT$11,"") -> 0 | AT17: =AO17*$AT$12 -> 0 | AV17: =IFERROR(AO17/AH17,0) -> 0 | AW17: =IFERROR(AQ17/AH17,0) -> 0 | AY17: =IFERROR(VLOOKUP(G17,選定!$C$3:$AG$100,28,FALSE),"0") -> 0 | AZ17: =C17 -> 0 | BA17: =D17 -> 0 | BB17: =IFERROR(VLOOKUP(G17,選定!$C$2:$AG$100,11,FALSE),"0") -> 0 | BC17: =IFERROR(VLOOKUP(G17,選定!$C$2:$AG$100,13,FALSE),"") | BD17: =IFERROR(VLOOKUP(G17,選定!$C$2:$AG$100,16,FALSE),"") | BE17: =IFERROR(VLOOKUP(G17,選定!$C$2:$AG$100,19,FALSE),"") | BF17: =IFERROR(VLOOKUP(G17,選定!$C$2:$AG$100,22,FALSE),"") | BG17: =L17 -> 0
A18: C | B18: =IF(C18="","",$C$5) | H18: =PRODUCT(I18,J18) -> 0 | J18: =IF(I18<>"",30,"") | L18: =SUM(M18:V18) -> 0 | W18: =($L18*$K18*$H18)/1000 -> 0 | X18: =$X$16 -> 30 | Y18: =ROUNDDOWN($W18*$X18,0) -> 0 | AA18: =IFERROR(VLOOKUP($G18,選定!$C$3:$AG$100,5,FALSE),0) -> 0 | AB18: =($AA18*$L18*$H18)/1000 -> 0 | AC18: =ROUNDDOWN($AB18*$AD18,0) -> 0 | AD18: =$AD$16 -> 30 | AE18: 3000 | AF18: 3 | AH18: =SUMIF($B$16:$B$45,$AG18,$L$16:$L$45) -> 0 | AI18: =SUMIF($B$16:$B$45,$AG18,LED計算式!$T$4:$T$33) -> 0 | AJ18: =SUMIF($B$16:$B$45,$AG18,LED計算式!$U$4) -> 0 | AK18: =IFERROR(AL18*LED計算式!$AC$2,"") -> 0 | AL18: =ROUNDDOWN((AI18+AJ18)/(100%-$AN18),-3) -> 0 | AM18: =IFERROR($AL18-$AI18-$AJ18,"") -> 0 | AN18: =$AN$16 -> 0.4 | AO18: =IFERROR(ROUNDDOWN($AL18*(100%-($AR$11+AU18)),-3),"") -> 0 | AP18: =AI18+AJ18 -> 0 | AQ18: =IFERROR(AO18-AI18-AJ18-AS18-AT18,"") -> 0 | AR18: =ROUNDDOWN(AO18*LED計算式!$AC$2,0) -> 0 | AS18: =IFERROR(AO18*$AT$11,"") -> 0 | AT18: =AO18*$AT$12 -> 0 | AV18: =IFERROR(AO18/AH18,0) -> 0 | AW18: =IFERROR(AQ18/AH18,0) -> 0 | AY18: =IFERROR(VLOOKUP(G18,選定!$C$3:$AG$100,28,FALSE),"0") -> 0 | AZ18: =C18 -> 0 | BA18: =D18 -> 0 | BB18: =IFERROR(VLOOKUP(G18,選定!$C$2:$AG$100,11,FALSE),"0") -> 0 | BC18: =IFERROR(VLOOKUP(G18,選定!$C$2:$AG$100,13,FALSE),"") | BD18: =IFERROR(VLOOKUP(G18,選定!$C$2:$AG$100,16,FALSE),"") | BE18: =IFERROR(VLOOKUP(G18,選定!$C$2:$AG$100,19,FALSE),"") | BF18: =IFERROR(VLOOKUP(G18,選定!$C$2:$AG$100,22,FALSE),"") | BG18: =L18 -> 0
A19: D | B19: =IF(C19="","",$C$5) | H19: =PRODUCT(I19,J19) -> 0 | J19: =IF(I19<>"",30,"") | L19: =SUM(M19:V19) -> 0 | W19: =($L19*$K19*$H19)/1000 -> 0 | X19: =$X$16 -> 30 | Y19: =ROUNDDOWN($W19*$X19,0) -> 0 | AA19: =IFERROR(VLOOKUP($G19,選定!$C$3:$AG$100,5,FALSE),0) -> 0 | AB19: =($AA19*$L19*$H19)/1000 -> 0 | AC19: =ROUNDDOWN($AB19*$AD19,0) -> 0 | AD19: =$AD$16 -> 30 | AE19: 3000 | AF19: 4 | AH19: =SUMIF($B$16:$B$45,$AG19,$L$16:$L$45) -> 0 | AI19: =SUMIF($B$16:$B$45,$AG19,LED計算式!$T$4:$T$33) -> 0 | AJ19: =SUMIF($B$16:$B$45,$AG19,LED計算式!$U$4) -> 0 | AK19: =IFERROR(AL19*LED計算式!$AC$2,"") -> 0 | AL19: =ROUNDDOWN((AI19+AJ19)/(100%-$AN19),-3) -> 0 | AM19: =IFERROR($AL19-$AI19-$AJ19,"") -> 0 | AN19: =$AN$16 -> 0.4 | AO19: =IFERROR(ROUNDDOWN($AL19*(100%-($AR$11+AU19)),-3),"") -> 0 | AP19: =AI19+AJ19 -> 0 | AQ19: =IFERROR(AO19-AI19-AJ19-AS19-AT19,"") -> 0 | AR19: =ROUNDDOWN(AO19*LED計算式!$AC$2,0) -> 0 | AS19: =IFERROR(AO19*$AT$11,"") -> 0 | AT19: =AO19*$AT$12 -> 0 | AV19: =IFERROR(AO19/AH19,0) -> 0 | AW19: =IFERROR(AQ19/AH19,0) -> 0 | AY19: =IFERROR(VLOOKUP(G19,選定!$C$3:$AG$100,28,FALSE),"0") -> 0 | AZ19: =C19 -> 0 | BA19: =D19 -> 0 | BB19: =IFERROR(VLOOKUP(G19,選定!$C$2:$AG$100,11,FALSE),"0") -> 0 | BC19: =IFERROR(VLOOKUP(G19,選定!$C$2:$AG$100,13,FALSE),"") | BD19: =IFERROR(VLOOKUP(G19,選定!$C$2:$AG$100,16,FALSE),"") | BE19: =IFERROR(VLOOKUP(G19,選定!$C$2:$AG$100,19,FALSE),"") | BF19: =IFERROR(VLOOKUP(G19,選定!$C$2:$AG$100,22,FALSE),"") | BG19: =L19 -> 0
A20: E | B20: =IF(C20="","",$C$5) | H20: =PRODUCT(I20,J20) -> 0 | J20: =IF(I20<>"",30,"") | L20: =SUM(M20:V20) -> 0 | W20: =($L20*$K20*$H20)/1000 -> 0 | X20: =$X$16 -> 30 | Y20: =ROUNDDOWN($W20*$X20,0) -> 0 | AA20: =IFERROR(VLOOKUP($G20,選定!$C$3:$AG$100,5,FALSE),0) -> 0 | AB20: =($AA20*$L20*$H20)/1000 -> 0 | AC20: =ROUNDDOWN($AB20*$AD20,0) -> 0 | AD20: =$AD$16 -> 30 | AE20: 3000 | AF20: 5 | AH20: =SUMIF($B$16:$B$45,$AG20,$L$16:$L$45) -> 0 | AI20: =SUMIF($B$16:$B$45,$AG20,LED計算式!$T$4:$T$33) -> 0 | AJ20: =SUMIF($B$16:$B$45,$AG20,LED計算式!$U$4) -> 0 | AK20: =IFERROR(AL20/54,"") -> 0 | AL20: =ROUNDDOWN((AI20+AJ20)/(100%-$AN20),0) -> 0 | AM20: =IFERROR($AL20-$AI20-$AJ20,"") -> 0 | AN20: =$AN$16 -> 0.4 | AO20: =IFERROR(ROUNDDOWN($AL20*(100%-($AR$11+AU20)),0),"") -> 0 | AP20: =AI20+AJ20 -> 0 | AQ20: =IFERROR(AO20-AI20-AJ20-AS20-AT20,"") -> 0 | AR20: =ROUNDDOWN(AO20/54,0) -> 0 | AS20: =IFERROR(AO20*$AT$11,"") -> 0 | AT20: =AO20*$AT$12 -> 0 | AV20: =IFERROR(AO20/AH20,0) -> 0 | AW20: =IFERROR(AQ20/AH20,0) -> 0 | AY20: =IFERROR(VLOOKUP(G20,選定!$C$3:$AG$100,28,FALSE),"0") -> 0 | AZ20: =C20 -> 0 | BA20: =D20 -> 0 | BB20: =IFERROR(VLOOKUP(G20,選定!$C$2:$AG$100,11,FALSE),"0") -> 0 | BC20: =IFERROR(VLOOKUP(G20,選定!$C$2:$AG$100,13,FALSE),"") | BD20: =IFERROR(VLOOKUP(G20,選定!$C$2:$AG$100,16,FALSE),"") | BE20: =IFERROR(VLOOKUP(G20,選定!$C$2:$AG$100,19,FALSE),"") | BF20: =IFERROR(VLOOKUP(G20,選定!$C$2:$AG$100,22,FALSE),"") | BG20: =L20 -> 0
A21: F | B21: =IF(C21="","",$C$5) | H21: =PRODUCT(I21,J21) -> 0 | J21: =IF(I21<>"",30,"") | L21: =SUM(M21:V21) -> 0 | W21: =($L21*$K21*$H21)/1000 -> 0 | X21: =$X$16 -> 30 | Y21: =ROUNDDOWN($W21*$X21,0) -> 0 | AA21: =IFERROR(VLOOKUP($G21,選定!$C$3:$AG$100,5,FALSE),0) -> 0 | AB21: =($AA21*$L21*$H21)/1000 -> 0 | AC21: =ROUNDDOWN($AB21*$AD21,0) -> 0 | AD21: =$AD$16 -> 30 | AE21: 3000 | AF21: 6 | AH21: =SUMIF($B$16:$B$45,$AG21,$L$16:$L$45) -> 0 | AI21: =SUMIF($B$16:$B$45,$AG21,LED計算式!$T$4:$T$33) -> 0 | AJ21: =SUMIF($B$16:$B$45,$AG21,LED計算式!$U$4) -> 0 | AK21: =IFERROR(AL21/54,"") -> 0 | AL21: =ROUNDDOWN((AI21+AJ21)/(100%-$AN21),0) -> 0 | AM21: =IFERROR($AL21-$AI21-$AJ21,"") -> 0 | AN21: =$AN$16 -> 0.4 | AO21: =IFERROR(ROUNDDOWN($AL21*(100%-($AR$11+AU21)),0),"") -> 0 | AP21: =AI21+AJ21 -> 0 | AQ21: =IFERROR(AO21-AI21-AJ21-AS21-AT21,"") -> 0 | AR21: =ROUNDDOWN(AO21/54,0) -> 0 | AS21: =IFERROR(AO21*$AT$11,"") -> 0 | AT21: =AO21*$AT$12 -> 0 | AV21: =IFERROR(AO21/AH21,0) -> 0 | AW21: =IFERROR(AQ21/AH21,0) -> 0 | AY21: =IFERROR(VLOOKUP(G21,選定!$C$3:$AG$100,28,FALSE),"0") -> 0 | AZ21: =C21 -> 0 | BA21: =D21 -> 0 | BB21: =IFERROR(VLOOKUP(G21,選定!$C$2:$AG$100,11,FALSE),"0") -> 0 | BC21: =IFERROR(VLOOKUP(G21,選定!$C$2:$AG$100,13,FALSE),"") | BD21: =IFERROR(VLOOKUP(G21,選定!$C$2:$AG$100,16,FALSE),"") | BE21: =IFERROR(VLOOKUP(G21,選定!$C$2:$AG$100,19,FALSE),"") | BF21: =IFERROR(VLOOKUP(G21,選定!$C$2:$AG$100,22,FALSE),"") | BG21: =L21 -> 0
A22: G | B22: =IF(C22="","",$C$5) | H22: =PRODUCT(I22,J22) -> 0 | J22: =IF(I22<>"",30,"") | L22: =SUM(M22:V22) -> 0 | W22: =($L22*$K22*$H22)/1000 -> 0 | X22: =$X$16 -> 30 | Y22: =ROUNDDOWN($W22*$X22,0) -> 0 | AA22: =IFERROR(VLOOKUP($G22,選定!$C$3:$AG$100,5,FALSE),0) -> 0 | AB22: =($AA22*$L22*$H22)/1000 -> 0 | AC22: =ROUNDDOWN($AB22*$AD22,0) -> 0 | AD22: =$AD$16 -> 30 | AE22: 3000 | AF22: 7 | AH22: =SUMIF($B$16:$B$45,$AG22,$L$16:$L$45) -> 0 | AI22: =SUMIF($B$16:$B$45,$AG22,LED計算式!$T$4:$T$33) -> 0 | AJ22: =SUMIF($B$16:$B$45,$AG22,LED計算式!$U$4) -> 0 | AK22: =IFERROR(AL22/54,"") -> 0 | AL22: =ROUNDDOWN((AI22+AJ22)/(100%-$AN22),0) -> 0 | AM22: =IFERROR($AL22-$AI22-$AJ22,"") -> 0 | AN22: =$AN$16 -> 0.4 | AO22: =IFERROR(ROUNDDOWN($AL22*(100%-($AR$11+AU22)),0),"") -> 0 | AP22: =AI22+AJ22 -> 0 | AQ22: =IFERROR(AO22-AI22-AJ22-AS22-AT22,"") -> 0 | AR22: =ROUNDDOWN(AO22/54,0) -> 0 | AS22: =IFERROR(AO22*$AT$11,"") -> 0 | AT22: =AO22*$AT$12 -> 0 | AV22: =IFERROR(AO22/AH22,0) -> 0 | AW22: =IFERROR(AQ22/AH22,0) -> 0 | AY22: =IFERROR(VLOOKUP(G22,選定!$C$3:$AG$100,28,FALSE),"0") -> 0 | AZ22: =C22 -> 0 | BA22: =D22 -> 0 | BB22: =IFERROR(VLOOKUP(G22,選定!$C$2:$AG$100,11,FALSE),"0") -> 0 | BC22: =IFERROR(VLOOKUP(G22,選定!$C$2:$AG$100,13,FALSE),"") | BD22: =IFERROR(VLOOKUP(G22,選定!$C$2:$AG$100,16,FALSE),"") | BE22: =IFERROR(VLOOKUP(G22,選定!$C$2:$AG$100,19,FALSE),"") | BF22: =IFERROR(VLOOKUP(G22,選定!$C$2:$AG$100,22,FALSE),"") | BG22: =L22 -> 0
A23: H | B23: =IF(C23="","",$C$5) | H23: =PRODUCT(I23,J23) -> 0 | J23: =IF(I23<>"",30,"") | L23: =SUM(M23:V23) -> 0 | W23: =($L23*$K23*$H23)/1000 -> 0 | X23: =$X$16 -> 30 | Y23: =ROUNDDOWN($W23*$X23,0) -> 0 | AA23: =IFERROR(VLOOKUP($G23,選定!$C$3:$AG$100,5,FALSE),0) -> 0 | AB23: =($AA23*$L23*$H23)/1000 -> 0 | AC23: =ROUNDDOWN($AB23*$AD23,0) -> 0 | AD23: =$AD$16 -> 30 | AE23: 3000 | AF23: 8 | AH23: =SUMIF($B$16:$B$45,$AG23,$L$16:$L$45) -> 0 | AI23: =SUMIF($B$16:$B$45,$AG23,LED計算式!$T$4:$T$33) -> 0 | AJ23: =SUMIF($B$16:$B$45,$AG23,LED計算式!$U$4) -> 0 | AK23: =IFERROR(AL23/54,"") -> 0 | AL23: =ROUNDDOWN((AI23+AJ23)/(100%-$AN23),0) -> 0 | AM23: =IFERROR($AL23-$AI23-$AJ23,"") -> 0 | AN23: =$AN$16 -> 0.4 | AO23: =IFERROR(ROUNDDOWN($AL23*(100%-($AR$11+AU23)),0),"") -> 0 | AP23: =AI23+AJ23 -> 0 | AQ23: =IFERROR(AO23-AI23-AJ23-AS23-AT23,"") -> 0 | AR23: =ROUNDDOWN(AO23/54,0) -> 0 | AS23: =IFERROR(AO23*$AT$11,"") -> 0 | AT23: =AO23*$AT$12 -> 0 | AV23: =IFERROR(AO23/AH23,0) -> 0 | AW23: =IFERROR(AQ23/AH23,0) -> 0 | AY23: =IFERROR(VLOOKUP(G23,選定!$C$3:$AG$100,28,FALSE),"0") -> 0 | AZ23: =C23 -> 0 | BA23: =D23 -> 0 | BB23: =IFERROR(VLOOKUP(G23,選定!$C$2:$AG$100,11,FALSE),"0") -> 0 | BC23: =IFERROR(VLOOKUP(G23,選定!$C$2:$AG$100,13,FALSE),"") | BD23: =IFERROR(VLOOKUP(G23,選定!$C$2:$AG$100,16,FALSE),"") | BE23: =IFERROR(VLOOKUP(G23,選定!$C$2:$AG$100,19,FALSE),"") | BF23: =IFERROR(VLOOKUP(G23,選定!$C$2:$AG$100,22,FALSE),"") | BG23: =L23 -> 0
A24: I | B24: =IF(C24="","",$C$5) | H24: =PRODUCT(I24,J24) -> 0 | J24: =IF(I24<>"",30,"") | L24: =SUM(M24:V24) -> 0 | W24: =($L24*$K24*$H24)/1000 -> 0 | X24: =$X$16 -> 30 | Y24: =ROUNDDOWN($W24*$X24,0) -> 0 | AA24: =IFERROR(VLOOKUP($G24,選定!$C$3:$AG$100,5,FALSE),0) -> 0 | AB24: =($AA24*$L24*$H24)/1000 -> 0 | AC24: =ROUNDDOWN($AB24*$AD24,0) -> 0 | AD24: =$AD$16 -> 30 | AE24: 3000 | AF24: 9 | AH24: =SUMIF($B$16:$B$45,$AG24,$L$16:$L$45) -> 0 | AI24: =SUMIF($B$16:$B$45,$AG24,LED計算式!$T$4:$T$33) -> 0 | AJ24: =SUMIF($B$16:$B$45,$AG24,LED計算式!$U$4) -> 0 | AK24: =IFERROR(AL24/54,"") -> 0 | AL24: =ROUNDDOWN((AI24+AJ24)/(100%-$AN24),0) -> 0 | AM24: =IFERROR($AL24-$AI24-$AJ24,"") -> 0 | AN24: =$AN$16 -> 0.4 | AO24: =IFERROR(ROUNDDOWN($AL24*(100%-($AR$11+AU24)),0),"") -> 0 | AP24: =AI24+AJ24 -> 0 | AQ24: =IFERROR(AO24-AI24-AJ24-AS24-AT24,"") -> 0 | AR24: =ROUNDDOWN(AO24/54,0) -> 0 | AS24: =IFERROR(AO24*$AT$11,"") -> 0 | AT24: =AO24*$AT$12 -> 0 | AV24: =IFERROR(AO24/AH24,0) -> 0 | AW24: =IFERROR(AQ24/AH24,0) -> 0 | AY24: =IFERROR(VLOOKUP(G24,選定!$C$3:$AG$100,28,FALSE),"0") -> 0 | AZ24: =C24 -> 0 | BA24: =D24 -> 0 | BB24: =IFERROR(VLOOKUP(G24,選定!$C$2:$AG$100,11,FALSE),"0") -> 0 | BC24: =IFERROR(VLOOKUP(G24,選定!$C$2:$AG$100,13,FALSE),"") | BD24: =IFERROR(VLOOKUP(G24,選定!$C$2:$AG$100,16,FALSE),"") | BE24: =IFERROR(VLOOKUP(G24,選定!$C$2:$AG$100,19,FALSE),"") | BF24: =IFERROR(VLOOKUP(G24,選定!$C$2:$AG$100,22,FALSE),"") | BG24: =L24 -> 0
A25: J | B25: =IF(C25="","",$C$5) | H25: =PRODUCT(I25,J25) -> 0 | J25: =IF(I25<>"",30,"") | L25: =SUM(M25:V25) -> 0 | W25: =($L25*$K25*$H25)/1000 -> 0 | X25: =$X$16 -> 30 | Y25: =ROUNDDOWN($W25*$X25,0) -> 0 | AA25: =IFERROR(VLOOKUP($G25,選定!$C$3:$AG$100,5,FALSE),0) -> 0 | AB25: =($AA25*$L25*$H25)/1000 -> 0 | AC25: =ROUNDDOWN($AB25*$AD25,0) -> 0 | AD25: =$AD$16 -> 30 | AE25: 3000 | AF25: 10 | AH25: =SUMIF($B$16:$B$45,$AG25,$L$16:$L$45) -> 0 | AI25: =SUMIF($B$16:$B$45,$AG25,LED計算式!$T$4:$T$33) -> 0 | AJ25: =SUMIF($B$16:$B$45,$AG25,LED計算式!$U$4) -> 0 | AK25: =IFERROR(AL25/54,"") -> 0 | AL25: =ROUNDDOWN((AI25+AJ25)/(100%-$AN25),0) -> 0 | AM25: =IFERROR($AL25-$AI25-$AJ25,"") -> 0 | AN25: =$AN$16 -> 0.4 | AO25: =IFERROR(ROUNDDOWN($AL25*(100%-($AR$11+AU25)),0),"") -> 0 | AP25: =AI25+AJ25 -> 0 | AQ25: =IFERROR(AO25-AI25-AJ25-AS25-AT25,"") -> 0 | AR25: =ROUNDDOWN(AO25/54,0) -> 0 | AS25: =IFERROR(AO25*$AT$11,"") -> 0 | AT25: =AO25*$AT$12 -> 0 | AV25: =IFERROR(AO25/AH25,0) -> 0 | AW25: =IFERROR(AQ25/AH25,0) -> 0 | AY25: =IFERROR(VLOOKUP(G25,選定!$C$3:$AG$100,28,FALSE),"0") -> 0 | AZ25: =C25 -> 0 | BA25: =D25 -> 0 | BB25: =IFERROR(VLOOKUP(G25,選定!$C$2:$AG$100,11,FALSE),"0") -> 0 | BC25: =IFERROR(VLOOKUP(G25,選定!$C$2:$AG$100,13,FALSE),"") | BD25: =IFERROR(VLOOKUP(G25,選定!$C$2:$AG$100,16,FALSE),"") | BE25: =IFERROR(VLOOKUP(G25,選定!$C$2:$AG$100,19,FALSE),"") | BF25: =IFERROR(VLOOKUP(G25,選定!$C$2:$AG$100,22,FALSE),"") | BG25: =L25 -> 0
A26: K | B26: =IF(C26="","",$C$5) | H26: =PRODUCT(I26,J26) -> 0 | J26: =IF(I26<>"",30,"") | L26: =SUM(M26:V26) -> 0 | W26: =($L26*$K26*$H26)/1000 -> 0 | X26: =$X$16 -> 30 | Y26: =ROUNDDOWN($W26*$X26,0) -> 0 | AA26: =IFERROR(VLOOKUP($G26,選定!$C$3:$AG$100,5,FALSE),0) -> 0 | AB26: =($AA26*$L26*$H26)/1000 -> 0 | AC26: =ROUNDDOWN($AB26*$AD26,0) -> 0 | AD26: =$AD$16 -> 30 | AE26: 3000 | AF26: 11 | AH26: =SUMIF($B$16:$B$45,$AG26,$L$16:$L$45) -> 0 | AI26: =SUMIF($B$16:$B$45,$AG26,LED計算式!$T$4:$T$33) -> 0 | AJ26: =SUMIF($B$16:$B$45,$AG26,LED計算式!$U$4) -> 0 | AK26: =IFERROR(AL26/54,"") -> 0 | AL26: =ROUNDDOWN((AI26+AJ26)/(100%-$AN26),0) -> 0 | AM26: =IFERROR($AL26-$AI26-$AJ26,"") -> 0 | AN26: =$AN$16 -> 0.4 | AO26: =IFERROR(ROUNDDOWN($AL26*(100%-($AR$11+AU26)),0),"") -> 0 | AP26: =AI26+AJ26 -> 0 | AQ26: =IFERROR(AO26-AI26-AJ26-AS26-AT26,"") -> 0 | AR26: =ROUNDDOWN(AO26/54,0) -> 0 | AS26: =IFERROR(AO26*$AT$11,"") -> 0 | AT26: =AO26*$AT$12 -> 0 | AV26: =IFERROR(AO26/AH26,0) -> 0 | AW26: =IFERROR(AQ26/AH26,0) -> 0 | AY26: =IFERROR(VLOOKUP(G26,選定!$C$3:$AG$100,28,FALSE),"0") -> 0 | AZ26: =C26 -> 0 | BA26: =D26 -> 0 | BB26: =IFERROR(VLOOKUP(G26,選定!$C$2:$AG$100,11,FALSE),"0") -> 0 | BC26: =IFERROR(VLOOKUP(G26,選定!$C$2:$AG$100,13,FALSE),"") | BD26: =IFERROR(VLOOKUP(G26,選定!$C$2:$AG$100,16,FALSE),"") | BE26: =IFERROR(VLOOKUP(G26,選定!$C$2:$AG$100,19,FALSE),"") | BF26: =IFERROR(VLOOKUP(G26,選定!$C$2:$AG$100,22,FALSE),"") | BG26: =L26 -> 0
A27: L | B27: =IF(C27="","",$C$5) | H27: =PRODUCT(I27,J27) -> 0 | J27: =IF(I27<>"",30,"") | L27: =SUM(M27:V27) -> 0 | W27: =($L27*$K27*$H27)/1000 -> 0 | X27: =$X$16 -> 30 | Y27: =ROUNDDOWN($W27*$X27,0) -> 0 | AA27: =IFERROR(VLOOKUP($G27,選定!$C$3:$AG$100,5,FALSE),0) -> 0 | AB27: =($AA27*$L27*$H27)/1000 -> 0 | AC27: =ROUNDDOWN($AB27*$AD27,0) -> 0 | AD27: =$AD$16 -> 30 | AE27: 3000 | AF27: 12 | AH27: =SUMIF($B$16:$B$45,$AG27,$L$16:$L$45) -> 0 | AI27: =SUMIF($B$16:$B$45,$AG27,LED計算式!$T$4:$T$33) -> 0 | AJ27: =SUMIF($B$16:$B$45,$AG27,LED計算式!$U$4) -> 0 | AK27: =IFERROR(AL27/54,"") -> 0 | AL27: =ROUNDDOWN((AI27+AJ27)/(100%-$AN27),0) -> 0 | AM27: =IFERROR($AL27-$AI27-$AJ27,"") -> 0 | AN27: =$AN$16 -> 0.4 | AO27: =IFERROR(ROUNDDOWN($AL27*(100%-($AR$11+AU27)),0),"") -> 0 | AP27: =AI27+AJ27 -> 0 | AQ27: =IFERROR(AO27-AI27-AJ27-AS27-AT27,"") -> 0 | AR27: =ROUNDDOWN(AO27/54,0) -> 0 | AS27: =IFERROR(AO27*$AT$11,"") -> 0 | AT27: =AO27*$AT$12 -> 0 | AV27: =IFERROR(AO27/AH27,0) -> 0 | AW27: =IFERROR(AQ27/AH27,0) -> 0 | AY27: =IFERROR(VLOOKUP(G27,選定!$C$3:$AG$100,28,FALSE),"0") -> 0 | AZ27: =C27 -> 0 | BA27: =D27 -> 0 | BB27: =IFERROR(VLOOKUP(G27,選定!$C$2:$AG$100,11,FALSE),"0") -> 0 | BC27: =IFERROR(VLOOKUP(G27,選定!$C$2:$AG$100,13,FALSE),"") | BD27: =IFERROR(VLOOKUP(G27,選定!$C$2:$AG$100,16,FALSE),"") | BE27: =IFERROR(VLOOKUP(G27,選定!$C$2:$AG$100,19,FALSE),"") | BF27: =IFERROR(VLOOKUP(G27,選定!$C$2:$AG$100,22,FALSE),"") | BG27: =L27 -> 0
A28: M | B28: =IF(C28="","",$C$5) | H28: =PRODUCT(I28,J28) -> 0 | J28: =IF(I28<>"",30,"") | L28: =SUM(M28:V28) -> 0 | W28: =($L28*$K28*$H28)/1000 -> 0 | X28: =$X$16 -> 30 | Y28: =ROUNDDOWN($W28*$X28,0) -> 0 | AA28: =IFERROR(VLOOKUP($G28,選定!$C$3:$AG$100,5,FALSE),0) -> 0 | AB28: =($AA28*$L28*$H28)/1000 -> 0 | AC28: =ROUNDDOWN($AB28*$AD28,0) -> 0 | AD28: =$AD$16 -> 30 | AE28: 3000 | AF28: 13 | AH28: =SUMIF($B$16:$B$45,$AG28,$L$16:$L$45) -> 0 | AI28: =SUMIF($B$16:$B$45,$AG28,LED計算式!$T$4:$T$33) -> 0 | AJ28: =SUMIF($B$16:$B$45,$AG28,LED計算式!$U$4) -> 0 | AK28: =IFERROR(AL28/54,"") -> 0 | AL28: =ROUNDDOWN((AI28+AJ28)/(100%-$AN28),0) -> 0 | AM28: =IFERROR($AL28-$AI28-$AJ28,"") -> 0 | AN28: =$AN$16 -> 0.4 | AO28: =IFERROR(ROUNDDOWN($AL28*(100%-($AR$11+AU28)),0),"") -> 0 | AP28: =AI28+AJ28 -> 0 | AQ28: =IFERROR(AO28-AI28-AJ28-AS28-AT28,"") -> 0 | AR28: =ROUNDDOWN(AO28/54,0) -> 0 | AS28: =IFERROR(AO28*$AT$11,"") -> 0 | AT28: =AO28*$AT$12 -> 0 | AV28: =IFERROR(AO28/AH28,0) -> 0 | AW28: =IFERROR(AQ28/AH28,0) -> 0 | AY28: =IFERROR(VLOOKUP(G28,選定!$C$3:$AG$100,28,FALSE),"0") -> 0 | AZ28: =C28 -> 0 | BA28: =D28 -> 0 | BB28: =IFERROR(VLOOKUP(G28,選定!$C$2:$AG$100,11,FALSE),"0") -> 0 | BC28: =IFERROR(VLOOKUP(G28,選定!$C$2:$AG$100,13,FALSE),"") | BD28: =IFERROR(VLOOKUP(G28,選定!$C$2:$AG$100,16,FALSE),"") | BE28: =IFERROR(VLOOKUP(G28,選定!$C$2:$AG$100,19,FALSE),"") | BF28: =IFERROR(VLOOKUP(G28,選定!$C$2:$AG$100,22,FALSE),"") | BG28: =L28 -> 0
A29: N | B29: =IF(C29="","",$C$5) | H29: =PRODUCT(I29,J29) -> 0 | J29: =IF(I29<>"",30,"") | L29: =SUM(M29:V29) -> 0 | W29: =($L29*$K29*$H29)/1000 -> 0 | X29: =$X$16 -> 30 | Y29: =ROUNDDOWN($W29*$X29,0) -> 0 | AA29: =IFERROR(VLOOKUP($G29,選定!$C$3:$AG$100,5,FALSE),0) -> 0 | AB29: =($AA29*$L29*$H29)/1000 -> 0 | AC29: =ROUNDDOWN($AB29*$AD29,0) -> 0 | AD29: =$AD$16 -> 30 | AE29: 3000 | AF29: 14 | AH29: =SUMIF($B$16:$B$45,$AG29,$L$16:$L$45) -> 0 | AI29: =SUMIF($B$16:$B$45,$AG29,LED計算式!$T$4:$T$33) -> 0 | AJ29: =SUMIF($B$16:$B$45,$AG29,LED計算式!$U$4) -> 0 | AK29: =IFERROR(AL29/54,"") -> 0 | AL29: =ROUNDDOWN((AI29+AJ29)/(100%-$AN29),0) -> 0 | AM29: =IFERROR($AL29-$AI29-$AJ29,"") -> 0 | AN29: =$AN$16 -> 0.4 | AO29: =IFERROR(ROUNDDOWN($AL29*(100%-($AR$11+AU29)),0),"") -> 0 | AP29: =AI29+AJ29 -> 0 | AQ29: =IFERROR(AO29-AI29-AJ29-AS29-AT29,"") -> 0 | AR29: =ROUNDDOWN(AO29/54,0) -> 0 | AS29: =IFERROR(AO29*$AT$11,"") -> 0 | AT29: =AO29*$AT$12 -> 0 | AV29: =IFERROR(AO29/AH29,0) -> 0 | AW29: =IFERROR(AQ29/AH29,0) -> 0 | AY29: =IFERROR(VLOOKUP(G29,選定!$C$3:$AG$100,28,FALSE),"0") -> 0 | AZ29: =C29 -> 0 | BA29: =D29 -> 0 | BB29: =IFERROR(VLOOKUP(G29,選定!$C$2:$AG$100,11,FALSE),"0") -> 0 | BC29: =IFERROR(VLOOKUP(G29,選定!$C$2:$AG$100,13,FALSE),"") | BD29: =IFERROR(VLOOKUP(G29,選定!$C$2:$AG$100,16,FALSE),"") | BE29: =IFERROR(VLOOKUP(G29,選定!$C$2:$AG$100,19,FALSE),"") | BF29: =IFERROR(VLOOKUP(G29,選定!$C$2:$AG$100,22,FALSE),"") | BG29: =L29 -> 0
A30: O | B30: =IF(C30="","",$C$5) | H30: =PRODUCT(I30,J30) -> 0 | J30: =IF(I30<>"",30,"") | L30: =SUM(M30:V30) -> 0 | W30: =($L30*$K30*$H30)/1000 -> 0 | X30: =$X$16 -> 30 | Y30: =ROUNDDOWN($W30*$X30,0) -> 0 | AA30: =IFERROR(VLOOKUP($G30,選定!$C$3:$AG$100,5,FALSE),0) -> 0 | AB30: =($AA30*$L30*$H30)/1000 -> 0 | AC30: =ROUNDDOWN($AB30*$AD30,0) -> 0 | AD30: =$AD$16 -> 30 | AE30: 3000 | AF30: 15 | AH30: =SUMIF($B$16:$B$45,$AG30,$L$16:$L$45) -> 0 | AI30: =SUMIF($B$16:$B$45,$AG30,LED計算式!$T$4:$T$33) -> 0 | AJ30: =SUMIF($B$16:$B$45,$AG30,LED計算式!$U$4) -> 0 | AK30: =IFERROR(AL30/54,"") -> 0 | AL30: =ROUNDDOWN((AI30+AJ30)/(100%-$AN30),0) -> 0 | AM30: =IFERROR($AL30-$AI30-$AJ30,"") -> 0 | AN30: =$AN$16 -> 0.4 | AO30: =IFERROR(ROUNDDOWN($AL30*(100%-($AR$11+AU30)),0),"") -> 0 | AP30: =AI30+AJ30 -> 0 | AQ30: =IFERROR(AO30-AI30-AJ30-AS30-AT30,"") -> 0 | AR30: =ROUNDDOWN(AO30/54,0) -> 0 | AS30: =IFERROR(AO30*$AT$11,"") -> 0 | AT30: =AO30*$AT$12 -> 0 | AV30: =IFERROR(AO30/AH30,0) -> 0 | AW30: =IFERROR(AQ30/AH30,0) -> 0 | AY30: =IFERROR(VLOOKUP(G30,選定!$C$3:$AG$100,28,FALSE),"0") -> 0 | AZ30: =C30 -> 0 | BA30: =D30 -> 0 | BB30: =IFERROR(VLOOKUP(G30,選定!$C$2:$AG$100,11,FALSE),"0") -> 0 | BC30: =IFERROR(VLOOKUP(G30,選定!$C$2:$AG$100,13,FALSE),"") | BD30: =IFERROR(VLOOKUP(G30,選定!$C$2:$AG$100,16,FALSE),"") | BE30: =IFERROR(VLOOKUP(G30,選定!$C$2:$AG$100,19,FALSE),"") | BF30: =IFERROR(VLOOKUP(G30,選定!$C$2:$AG$100,22,FALSE),"") | BG30: =L30 -> 0
A31: P | B31: =IF(C31="","",$C$5) | H31: =PRODUCT(I31,J31) -> 0 | J31: =IF(I31<>"",30,"") | L31: =SUM(M31:V31) -> 0 | W31: =($L31*$K31*$H31)/1000 -> 0 | X31: =$X$16 -> 30 | Y31: =ROUNDDOWN($W31*$X31,0) -> 0 | AA31: =IFERROR(VLOOKUP($G31,選定!$C$3:$AG$100,5,FALSE),0) -> 0 | AB31: =($AA31*$L31*$H31)/1000 -> 0 | AC31: =ROUNDDOWN($AB31*$AD31,0) -> 0 | AD31: =$AD$16 -> 30 | AE31: 3000 | AF31: 16 | AH31: =SUMIF($B$16:$B$45,$AG31,$L$16:$L$45) -> 0 | AI31: =SUMIF($B$16:$B$45,$AG31,LED計算式!$T$4:$T$33) -> 0 | AJ31: =SUMIF($B$16:$B$45,$AG31,LED計算式!$U$4) -> 0 | AK31: =IFERROR(AL31/54,"") -> 0 | AL31: =ROUNDDOWN((AI31+AJ31)/(100%-$AN31),0) -> 0 | AM31: =IFERROR($AL31-$AI31-$AJ31,"") -> 0 | AN31: =$AN$16 -> 0.4 | AO31: =IFERROR(ROUNDDOWN($AL31*(100%-($AR$11+AU31)),0),"") -> 0 | AP31: =AI31+AJ31 -> 0 | AQ31: =IFERROR(AO31-AI31-AJ31-AS31-AT31,"") -> 0 | AR31: =ROUNDDOWN(AO31/54,0) -> 0 | AS31: =IFERROR(AO31*$AT$11,"") -> 0 | AT31: =AO31*$AT$12 -> 0 | AV31: =IFERROR(AO31/AH31,0) -> 0 | AW31: =IFERROR(AQ31/AH31,0) -> 0 | AY31: =IFERROR(VLOOKUP(G31,選定!$C$3:$AG$100,28,FALSE),"0") -> 0 | AZ31: =C31 -> 0 | BA31: =D31 -> 0 | BB31: =IFERROR(VLOOKUP(G31,選定!$C$2:$AG$100,11,FALSE),"0") -> 0 | BC31: =IFERROR(VLOOKUP(G31,選定!$C$2:$AG$100,13,FALSE),"") | BD31: =IFERROR(VLOOKUP(G31,選定!$C$2:$AG$100,16,FALSE),"") | BE31: =IFERROR(VLOOKUP(G31,選定!$C$2:$AG$100,19,FALSE),"") | BF31: =IFERROR(VLOOKUP(G31,選定!$C$2:$AG$100,22,FALSE),"") | BG31: =L31 -> 0
... A45: AD | B45: =IF(C45="","",$C$5) | H45: =PRODUCT(I45,J45) -> 0 | J45: =IF(I45<>"",30,"") | L45: =SUM(M45:V45) -> 0 | W45: =($L45*$K45*$H45)/1000 -> 0 | X45: =$X$16 -> 30 | Y45: =ROUNDDOWN($W45*$X45,0) -> 0 | AA45: =IFERROR(VLOOKUP($G45,選定!$C$3:$AG$100,5,FALSE),0) -> 0 | AB45: =($AA45*$L45*$H45)/1000 -> 0 | AC45: =ROUNDDOWN($AB45*$AD45,0) -> 0 | AD45: =$AD$16 -> 30 | AE45: 3000 | AF45: 30 | AH45: =SUMIF($B$16:$B$45,$AG45,$L$16:$L$45) -> 0 | AI45: =SUMIF($B$16:$B$45,$AG45,LED計算式!$T$4:$T$33) -> 0 | AJ45: =SUMIF($B$16:$B$45,$AG45,LED計算式!$U$4) -> 0 | AK45: =IFERROR(AL45/54,"") -> 0 | AL45: =ROUNDDOWN((AI45+AJ45)/(100%-$AN45),0) -> 0 | AM45: =IFERROR($AL45-$AI45-$AJ45,"") -> 0 | AN45: =$AN$16 -> 0.4 | AO45: =IFERROR(ROUNDDOWN($AL45*(100%-($AR$11+AU45)),0),"") -> 0 | AP45: =AI45+AJ45 -> 0 | AQ45: =IFERROR(AO45-AI45-AJ45-AS45-AT45,"") -> 0 | AR45: =ROUNDDOWN(AO45/54,0) -> 0 | AS45: =IFERROR(AO45*$AT$11,"") -> 0 | AT45: =AO45*$AT$12 -> 0 | AV45: =IFERROR(AO45/AH45,0) -> 0 | AW45: =IFERROR(AQ45/AH45,0) -> 0 | AY45: =IFERROR(VLOOKUP(G45,選定!$C$3:$AG$100,28,FALSE),"0") -> 0 | AZ45: =C45 -> 0 | BA45: =D45 -> 0 | BB45: =IFERROR(VLOOKUP(G45,選定!$C$2:$AG$100,11,FALSE),"0") -> 0 | BC45: =IFERROR(VLOOKUP(G45,選定!$C$2:$AG$100,13,FALSE),"") | BD45: =IFERROR(VLOOKUP(G45,選定!$C$2:$AG$100,16,FALSE),"") | BE45: =IFERROR(VLOOKUP(G45,選定!$C$2:$AG$100,19,FALSE),"") | BF45: =IFERROR(VLOOKUP(G45,選定!$C$2:$AG$100,22,FALSE),"") | BG45: =L45 -> 0
B47: 【LED済み箇所】
B48: 物件名 | C48: 試算エリア | D48: 照明種別 | E48: 現調備考 | L48: 電球数 | M48: 1階 | N48: 2階 | O48: 3階 | P48: 4階 | Q48: 5階 | R48: 6階 | S48: 7階 | T48: 8階 | U48: 9階 | V48: 10階 | W48: 除外理由 | AC48: アドバイス
A49: 1 | B49: =IF(C49="","",$C$5) | L49: =SUM(M49:V49) -> 0
A50: 2 | B50: =IF(C50="","",$C$5) | L50: =SUM(M50:V50) -> 0
A51: 3 | B51: =IF(C51="","",$C$5) | L51: =SUM(M51:V51) -> 0
A52: 4 | B52: =IF(C52="","",$C$5) | L52: =SUM(M52:V52) -> 0
A53: 5 | B53: =IF(C53="","",$C$5) | L53: =SUM(M53:V53) -> 0
A54: 6 | B54: =IF(C54="","",$C$5) | L54: =SUM(M54:V54) -> 0
...

Sheet 見積チェック
A1: LED見積作成チェックシート
A3: ✓ | B3: No. | C3: チェック項目 | D3: 備考
B4: 1 | C4: ◎ 器具の大きさ
B5: 2 | C5: ◎ 防滴か否か確認
B6: 3 | C6: ◎ 色温度
B7: 4 | C7: ◎ 見積書のシートの別置作業がない場合非表示
B8: 5 | C8: 消費電力を入れてない
B9: 6 | C9: 高所作業か否か
B10: 7 | C10: 照明種別が多い時(15個以上)見積反映
B11: 8 | C11: 除外理由記入漏れ
B12: 9 | C12: 表紙の確認(連名などの確認)
B13: 10 | C13: 工事の特記事項の記入→現調シートの内容を反映
B14: 11 | C14: W数(安定器が入ってないケースが多い)
B15: 12 | C15: L19とAH14がイコールか(数量の確認)
A17: ✕ チェックを全削除
A18: ※ チェックボックスを手動でクリアして次の案件へ

Sheet ①表紙
A2: =☆入力!C5 -> 0
A25: =代理店入力用!N3 -> 株式会社ニッショー | I25: バズエリア株式会社
A26: =代理店入力用!N4&代理店入力用!N5 | I26: 〒151-0071 東京都渋谷区本町2-6-3 D'sVARIE初台ビル3F
A27: ="TEL： "&代理店入力用!N6 -> TEL： 管理担当営業所へお問い合わせ下さい。 | I27: TEL：03-4586-6561 FAX：03-6812-9253
A28: ="担当："&代理店入力用!N7 -> 担当：物件担当者 | N28: 1

Sheet ②LEDをいま検討しないといけない理由
A1: ～LEDをいま検討しないといけない理由～
B2: ①蛍光灯・白熱電球がなくなってしまう為
C6: 電力量料金（円）＝消費電力（kW）×点灯時間（時間）×電力量単価（円kW）
C8: ◇電力量単価は、頂いた電力明細に準ずる単価で計算しておりますが、ご提出頂けていない場合には地域電力の単価を基にして概算にて算出しております。
B10: 2、交換コストの算出方法
C12: 管理会社からの電球が切れた場合の1球あたりの交換費用を基に算出しております。
C13: ◇本シミュレーションでは、1球あたり、 | M13: =☆入力!AR9 -> 0 | P13: にて計算しております。管理会社に確認出来ていない場合には2,500円/球にて算出しております。
C14: ※全国不動産管理会社様の相場は2,000円～3,000円、高い会社で5,000円となっております。
B16: 3、導入パターン
C18: 一括購入 | Q18: or | Z18: リース
B21: ②蛍光灯→品薄、LED→原材料高騰・円安でそれぞれ値上がり続けている為
B24: 4、非常用専用照明に関して
C26: 弊社のご提案では、コストメリットを出して利回りを良くすることを重視して作成しておりますので、非常用専用照明（非常時にか点灯しない照明）は基本的に見積から除外をしております。
C27: ただ、非常用専用照明も消防法上定期的なバッテリー交換が必要で、各メーカーLEDに切り替えがなされておりますので次回交換時にはLED化が必須となります。
C28: 交換をする場合には別途、御見積を致しますのでお申しつけください。
B30: 5、器具デザインカスタマイズに関して
AY32: 2

Sheet ③LED導入のメリット
B2: LED照明導入のメリット
O31: 3

Sheet ②前a
A1: ～現地調査結果および既存照明にかかる10年間のランニングコスト～
R3: 既存照明の場合 | AF3: 既存照明に対してかかっている10年間のランニングコスト
A6: No | C6: =LED計算式!M32 -> 試算エリア | G6: 照明種別 | L6: 月間点灯 | P6: 数量 | R6: 消費電力 | U6: 電力量 | Y6: 使用料(月) | AF6: ①10年間でかかる電気料金の総額＝ | AS6: =Y39*120 -> 0
A8: 1 | C8: =IF($C$6=☆入力!$B$15,☆入力!$B16,☆入力!$C16) -> 0 | G8: =☆入力!D16 -> 0 | L8: =☆入力!H16 -> 0 | P8: =☆入力!L16 -> 0 | R8: =☆入力!K16 -> 0 | U8: =☆入力!W16 -> 0 | Y8: =☆入力!Y16 -> 0 | AG8: 計算式：毎月の電気料金 | AO8: =Y39 -> 0 | AS8: ×10年間（120ヵ月）
A9: 2 | C9: =IF($C$6=☆入力!$B$15,☆入力!$B17,☆入力!$C17) -> 0 | G9: =☆入力!D17 -> 0 | L9: =☆入力!H17 -> 0 | P9: =☆入力!L17 -> 0 | R9: =☆入力!K17 -> 0 | U9: =☆入力!W17 -> 0 | Y9: =☆入力!Y17 -> 0 | AS9: +
A10: 3 | C10: =IF($C$6=☆入力!$B$15,☆入力!$B18,☆入力!$C18) -> 0 | G10: =☆入力!D18 -> 0 | L10: =☆入力!H18 -> 0 | P10: =☆入力!L18 -> 0 | R10: =☆入力!K18 -> 0 | U10: =☆入力!W18 -> 0 | Y10: =☆入力!Y18 -> 0
A11: 4 | C11: =IF($C$6=☆入力!$B$15,☆入力!$B19,☆入力!$C19) -> 0 | G11: =☆入力!D19 -> 0 | L11: =☆入力!H19 -> 0 | P11: =☆入力!L19 -> 0 | R11: =☆入力!K19 -> 0 | U11: =☆入力!W19 -> 0 | Y11: =☆入力!Y19 -> 0 | AF11: ②10年間でかかる白熱球の交換コストの総額＝
A12: 5 | C12: =IF($C$6=☆入力!$B$15,☆入力!$B20,☆入力!$C20) -> 0 | G12: =☆入力!D20 -> 0 | L12: =☆入力!H20 -> 0 | P12: =☆入力!L20 -> 0 | R12: =☆入力!K20 -> 0 | U12: =☆入力!W20 -> 0 | Y12: =☆入力!Y20 -> 0
A13: 6 | C13: =IF($C$6=☆入力!$B$15,☆入力!$B21,☆入力!$C21) -> 0 | G13: =☆入力!D21 -> 0 | L13: =☆入力!H21 -> 0 | P13: =☆入力!L21 -> 0 | R13: =☆入力!K21 -> 0 | U13: =☆入力!W21 -> 0 | Y13: =☆入力!Y21 -> 0 | AS13: =(AN15*☆入力!AR9*7)+(AN16*☆入力!AR9*15) -> 0
A14: 7 | C14: =IF($C$6=☆入力!$B$15,☆入力!$B22,☆入力!$C22) -> 0 | G14: =☆入力!D22 -> 0 | L14: =☆入力!H22 -> 0 | P14: =☆入力!L22 -> 0 | R14: =☆入力!K22 -> 0 | U14: =☆入力!W22 -> 0 | Y14: =☆入力!Y22 -> 0
A15: 8 | C15: =IF($C$6=☆入力!$B$15,☆入力!$B23,☆入力!$C23) -> 0 | G15: =☆入力!D23 -> 0 | L15: =☆入力!H23 -> 0 | P15: =☆入力!L23 -> 0 | R15: =☆入力!K23 -> 0 | U15: =☆入力!W23 -> 0 | Y15: =☆入力!Y23 -> 0 | AG15: 月間点灯360hの場合： | AN15: =LED計算式!N16 -> 0 | AQ15: ="× "&TEXT(☆入力!AR9,"#,#00")&"円（※1）× 7回（※2）" -> × 00円（※1）× 7回（※2）
A16: 9 | C16: =IF($C$6=☆入力!$B$15,☆入力!$B24,☆入力!$C24) -> 0 | G16: =☆入力!D24 -> 0 | L16: =☆入力!H24 -> 0 | P16: =☆入力!L24 -> 0 | R16: =☆入力!K24 -> 0 | U16: =☆入力!W24 -> 0 | Y16: =☆入力!Y24 -> 0 | AG16: 月間点灯720hの場合： | AN16: =LED計算式!N17 -> 0 | AQ16: ="× "&TEXT(☆入力!AR9,"#,#00")&"円（※1）× 15回（※3）" -> × 00円（※1）× 15回（※3）
A17: 10 | C17: =IF($C$6=☆入力!$B$15,☆入力!$B25,☆入力!$C25) -> 0 | G17: =☆入力!D25 -> 0 | L17: =☆入力!H25 -> 0 | P17: =☆入力!L25 -> 0 | R17: =☆入力!K25 -> 0 | U17: =☆入力!W25 -> 0 | Y17: =☆入力!Y25 -> 0 | AG17: ="(※1)白熱球の1球あたりの交換費用⇒"&TEXT(☆入力!AR9,"#,#00")&"円で計算(管理会社に委託している場合の平均)" -> (※1)白熱球の1球あたりの交換費用⇒00円で計算(管理会社に委託している場合の平均)
A18: 11 | C18: =IF($C$6=☆入力!$B$15,☆入力!$B26,☆入力!$C26) -> 0 | G18: =☆入力!D26 -> 0 | L18: =☆入力!H26 -> 0 | P18: =☆入力!L26 -> 0 | R18: =☆入力!K26 -> 0 | U18: =☆入力!W26 -> 0 | Y18: =☆入力!Y26 -> 0 | AG18: (※2)月間点灯360時間の場合⇒電球寿命を1年5ヵ月として10年間で7回の交換を想定して算出
A19: 12 | C19: =IF($C$6=☆入力!$B$15,☆入力!$B27,☆入力!$C27) -> 0 | G19: =☆入力!D27 -> 0 | L19: =☆入力!H27 -> 0 | P19: =☆入力!L27 -> 0 | R19: =☆入力!K27 -> 0 | U19: =☆入力!W27 -> 0 | Y19: =☆入力!Y27 -> 0 | AG19: (※3)月間点灯720時間の場合⇒電球寿命を8ヵ月として10年間で15回の交換を想定して算出
A20: 13 | C20: =IF($C$6=☆入力!$B$15,☆入力!$B28,☆入力!$C28) -> 0 | G20: =☆入力!D28 -> 0 | L20: =☆入力!H28 -> 0 | P20: =☆入力!L28 -> 0 | R20: =☆入力!K28 -> 0 | U20: =☆入力!W28 -> 0 | Y20: =☆入力!Y28 -> 0 | AS20: +
A21: 14 | C21: =IF($C$6=☆入力!$B$15,☆入力!$B29,☆入力!$C29) -> 0 | G21: =☆入力!D29 -> 0 | L21: =☆入力!H29 -> 0 | P21: =☆入力!L29 -> 0 | R21: =☆入力!K29 -> 0 | U21: =☆入力!W29 -> 0 | Y21: =☆入力!Y29 -> 0
A22: 15 | C22: =IF($C$6=☆入力!$B$15,☆入力!$B30,☆入力!$C30) -> 0 | G22: =☆入力!D30 -> 0 | L22: =☆入力!H30 -> 0 | P22: =☆入力!L30 -> 0 | R22: =☆入力!K30 -> 0 | U22: =☆入力!W30 -> 0 | Y22: =☆入力!Y30 -> 0 | AF22: ③10年間でかかる非常灯のバッテリー交換コストの総額＝
A23: 16 | C23: =IF($C$6=☆入力!$B$15,☆入力!$B31,☆入力!$C31) -> 0 | G23: =☆入力!D31 -> 0 | L23: =☆入力!H31 -> 0 | P23: =☆入力!L31 -> 0 | R23: =☆入力!K31 -> 0 | U23: =☆入力!W31 -> 0 | Y23: =☆入力!Y31 -> 0
A24: 17 | C24: =IF($C$6=☆入力!$B$15,☆入力!$B32,☆入力!$C32) -> 0 | G24: =☆入力!D32 -> 0 | L24: =☆入力!H32 -> 0 | P24: =☆入力!L32 -> 0 | R24: =☆入力!K32 -> 0 | U24: =☆入力!W32 -> 0 | Y24: =☆入力!Y32 -> 0 | AS24: =☆入力!L12*10000*2 -> 0
A25: 18 | C25: =IF($C$6=☆入力!$B$15,☆入力!$B33,☆入力!$C33) -> 0 | G25: =☆入力!D33 -> 0 | L25: =☆入力!H33 -> 0 | P25: =☆入力!L33 -> 0 | R25: =☆入力!K33 -> 0 | U25: =☆入力!W33 -> 0 | Y25: =☆入力!Y33 -> 0
A26: 19 | C26: =IF($C$6=☆入力!$B$15,☆入力!$B34,☆入力!$C34) -> 0 | G26: =☆入力!D34 -> 0 | L26: =☆入力!H34 -> 0 | P26: =☆入力!L34 -> 0 | R26: =☆入力!K34 -> 0 | U26: =☆入力!W34 -> 0 | Y26: =☆入力!Y34 -> 0 | AG26: 計算式：非常照明の総数 | AO26: =☆入力!L12 -> 0 | AR26: ×10,000円（※4）×2回（※5）
A27: 20 | C27: =IF($C$6=☆入力!$B$15,☆入力!$B35,☆入力!$C35) -> 0 | G27: =☆入力!D35 -> 0 | L27: =☆入力!H35 -> 0 | P27: =☆入力!L35 -> 0 | R27: =☆入力!K35 -> 0 | U27: =☆入力!W35 -> 0 | Y27: =☆入力!Y35 -> 0
A28: 21 | C28: =IF($C$6=☆入力!$B$15,☆入力!$B36,☆入力!$C36) -> 0 | G28: =☆入力!D36 -> 0 | L28: =☆入力!H36 -> 0 | P28: =☆入力!L36 -> 0 | R28: =☆入力!K36 -> 0 | U28: =☆入力!W36 -> 0 | Y28: =☆入力!Y36 -> 0 | AG28: (※4)非常灯のバッテリー交換費用⇒10,000円で計算(管理会社に委託している場合の平均)
A29: 22 | C29: =IF($C$6=☆入力!$B$15,☆入力!$B37,☆入力!$C37) -> 0 | G29: =☆入力!D37 -> 0 | L29: =☆入力!H37 -> 0 | P29: =☆入力!L37 -> 0 | R29: =☆入力!K37 -> 0 | U29: =☆入力!W37 -> 0 | Y29: =☆入力!Y37 -> 0 | AG29: (※5)内蔵バッテリーの寿命⇒5年として10年間で2回交換することを想定して算出
A30: 23 | C30: =IF($C$6=☆入力!$B$15,☆入力!$B38,☆入力!$C38) -> 0 | G30: =☆入力!D38 -> 0 | L30: =☆入力!H38 -> 0 | P30: =☆入力!L38 -> 0 | R30: =☆入力!K38 -> 0 | U30: =☆入力!W38 -> 0 | Y30: =☆入力!Y38 -> 0
A31: 24 | C31: =IF($C$6=☆入力!$B$15,☆入力!$B39,☆入力!$C39) -> 0 | G31: =☆入力!D39 -> 0 | L31: =☆入力!H39 -> 0 | P31: =☆入力!L39 -> 0 | R31: =☆入力!K39 -> 0 | U31: =☆入力!W39 -> 0 | Y31: =☆入力!Y39 -> 0
A32: 25 | C32: =IF($C$6=☆入力!$B$15,☆入力!$B40,☆入力!$C40) -> 0 | G32: =☆入力!D40 -> 0 | L32: =☆入力!H40 -> 0 | P32: =☆入力!L40 -> 0 | R32: =☆入力!K40 -> 0 | U32: =☆入力!W40 -> 0 | Y32: =☆入力!Y40 -> 0
A33: 26 | C33: =IF($C$6=☆入力!$B$15,☆入力!$B41,☆入力!$C41) -> 0 | G33: =☆入力!D41 -> 0 | L33: =☆入力!H41 -> 0 | P33: =☆入力!L41 -> 0 | R33: =☆入力!K41 -> 0 | U33: =☆入力!W41 -> 0 | Y33: =☆入力!Y41 -> 0
A34: 27 | C34: =IF($C$6=☆入力!$B$15,☆入力!$B42,☆入力!$C42) -> 0 | G34: =☆入力!D42 -> 0 | L34: =☆入力!H42 -> 0 | P34: =☆入力!L42 -> 0 | R34: =☆入力!K42 -> 0 | U34: =☆入力!W42 -> 0 | Y34: =☆入力!Y42 -> 0
A35: 28 | C35: =IF($C$6=☆入力!$B$15,☆入力!$B43,☆入力!$C43) -> 0 | G35: =☆入力!D43 -> 0 | L35: =☆入力!H43 -> 0 | P35: =☆入力!L43 -> 0 | R35: =☆入力!K43 -> 0 | U35: =☆入力!W43 -> 0 | Y35: =☆入力!Y43 -> 0
A36: 29 | C36: =IF($C$6=☆入力!$B$15,☆入力!$B44,☆入力!$C44) -> 0 | G36: =☆入力!D44 -> 0 | L36: =☆入力!H44 -> 0 | P36: =☆入力!L44 -> 0 | R36: =☆入力!K44 -> 0 | U36: =☆入力!W44 -> 0 | Y36: =☆入力!Y44 -> 0
A37: 30 | C37: =IF($C$6=☆入力!$B$15,☆入力!$B45,☆入力!$C45) -> 0 | G37: =☆入力!D45 -> 0 | L37: =☆入力!H45 -> 0 | P37: =☆入力!L45 -> 0 | R37: =☆入力!K45 -> 0 | U37: =☆入力!W45 -> 0 | Y37: =☆入力!Y45 -> 0
K38: ※電気代の中で「照明にかかっている電気代」のみを算出しております
K39: 合計 | P39: =SUM(P8:Q37) -> 0 | R39: - | U39: =SUM(U8:X37) -> 0 | Y39: =SUM(Y8:AB37) -> 0 | AF39: ★10年間で既存照明に対してかかるランニングコストの総額＝
AS41: =AS6+AS13+AS24 -> 0
BD44: 3

Sheet ③後a
A1: ～LED照明導入後の削減費用および10年間のランニングコスト～
R3: LED照明交換後 | AF3: LED照明に交換した場合の10年間のランニングコスト
A6: No | C6: =LED計算式!M32 -> 試算エリア | G6: 照明種別 | L6: 月間点灯 | P6: 数量 | R6: 消費電力 | U6: 電力量 | Y6: 使用料(月) | AF6: ①10年間でかかる電気料金の総額＝ | AS6: =Y39*120 -> 0
A8: 1 | C8: =IF($C$6=☆入力!$B$15,☆入力!$B16,☆入力!$C16) -> 0 | G8: =☆入力!D16 -> 0 | L8: =☆入力!H16 -> 0 | P8: =☆入力!L16 -> 0 | R8: =☆入力!AA16 -> 0 | U8: =☆入力!AB16 -> 0 | Y8: =☆入力!AC16 -> 0 | AG8: 計算式：毎月の電気料金 | AO8: =Y39 -> 0 | AS8: ×10年間（120ヵ月）
A9: 2 | C9: =IF($C$6=☆入力!$B$15,☆入力!$B17,☆入力!$C17) -> 0 | G9: =☆入力!D17 -> 0 | L9: =☆入力!H17 -> 0 | P9: =☆入力!L17 -> 0 | R9: =☆入力!AA17 -> 0 | U9: =☆入力!AB17 -> 0 | Y9: =☆入力!AC17 -> 0 | AS9: +
A10: 3 | C10: =IF($C$6=☆入力!$B$15,☆入力!$B18,☆入力!$C18) -> 0 | G10: =☆入力!D18 -> 0 | L10: =☆入力!H18 -> 0 | P10: =☆入力!L18 -> 0 | R10: =☆入力!AA18 -> 0 | U10: =☆入力!AB18 -> 0 | Y10: =☆入力!AC18 -> 0 | BF10: ※②が「0円」場合には左に移動してください
A11: 4 | C11: =IF($C$6=☆入力!$B$15,☆入力!$B19,☆入力!$C19) -> 0 | G11: =☆入力!D19 -> 0 | L11: =☆入力!H19 -> 0 | P11: =☆入力!L19 -> 0 | R11: =☆入力!AA19 -> 0 | U11: =☆入力!AB19 -> 0 | Y11: =☆入力!AC19 -> 0 | AF11: ②10年間でかかるLED照明の交換コストの総額＝
A12: 5 | C12: =IF($C$6=☆入力!$B$15,☆入力!$B20,☆入力!$C20) -> 0 | G12: =☆入力!D20 -> 0 | L12: =☆入力!H20 -> 0 | P12: =☆入力!L20 -> 0 | R12: =☆入力!AA20 -> 0 | U12: =☆入力!AB20 -> 0 | Y12: =☆入力!AC20 -> 0
A13: 6 | C13: =IF($C$6=☆入力!$B$15,☆入力!$B21,☆入力!$C21) -> 0 | G13: =☆入力!D21 -> 0 | L13: =☆入力!H21 -> 0 | P13: =☆入力!L21 -> 0 | R13: =☆入力!AA21 -> 0 | U13: =☆入力!AB21 -> 0 | Y13: =☆入力!AC21 -> 0 | AS13: =AN16*3000*1 -> 0
A14: 7 | C14: =IF($C$6=☆入力!$B$15,☆入力!$B22,☆入力!$C22) -> 0 | G14: =☆入力!D22 -> 0 | L14: =☆入力!H22 -> 0 | P14: =☆入力!L22 -> 0 | R14: =☆入力!AA22 -> 0 | U14: =☆入力!AB22 -> 0 | Y14: =☆入力!AC22 -> 0
A15: 8 | C15: =IF($C$6=☆入力!$B$15,☆入力!$B23,☆入力!$C23) -> 0 | G15: =☆入力!D23 -> 0 | L15: =☆入力!H23 -> 0 | P15: =☆入力!L23 -> 0 | R15: =☆入力!AA23 -> 0 | U15: =☆入力!AB23 -> 0 | Y15: =☆入力!AC23 -> 0 | AG15: 月間点灯360hの場合： | AN15: =LED計算式!N16 -> 0 | AQ15: ="× "&TEXT(☆入力!AR9,"#,#00")&"円（※1）× 0回（※2）" -> × 00円（※1）× 0回（※2）
A16: 9 | C16: =IF($C$6=☆入力!$B$15,☆入力!$B24,☆入力!$C24) -> 0 | G16: =☆入力!D24 -> 0 | L16: =☆入力!H24 -> 0 | P16: =☆入力!L24 -> 0 | R16: =☆入力!AA24 -> 0 | U16: =☆入力!AB24 -> 0 | Y16: =☆入力!AC24 -> 0 | AG16: 月間点灯720hの場合： | AN16: =LED計算式!N17 -> 0 | AQ16: × 3,000円（※1）× 1回（※3）
A17: 10 | C17: =IF($C$6=☆入力!$B$15,☆入力!$B25,☆入力!$C25) -> 0 | G17: =☆入力!D25 -> 0 | L17: =☆入力!H25 -> 0 | P17: =☆入力!L25 -> 0 | R17: =☆入力!AA25 -> 0 | U17: =☆入力!AB25 -> 0 | Y17: =☆入力!AC25 -> 0 | AG17: (※1)月間点灯720時間の場合、光源部分の交換を3,000円/球として算出
A18: 11 | C18: =IF($C$6=☆入力!$B$15,☆入力!$B26,☆入力!$C26) -> 0 | G18: =☆入力!D26 -> 0 | L18: =☆入力!H26 -> 0 | P18: =☆入力!L26 -> 0 | R18: =☆入力!AA26 -> 0 | U18: =☆入力!AB26 -> 0 | Y18: =☆入力!AC26 -> 0 | AG18: (※3)月間点灯720時間の場合、10年間で1回の光源部分交換を想定して算出
A19: 12 | C19: =IF($C$6=☆入力!$B$15,☆入力!$B27,☆入力!$C27) -> 0 | G19: =☆入力!D27 -> 0 | L19: =☆入力!H27 -> 0 | P19: =☆入力!L27 -> 0 | R19: =☆入力!AA27 -> 0 | U19: =☆入力!AB27 -> 0 | Y19: =☆入力!AC27 -> 0
A20: 13 | C20: =IF($C$6=☆入力!$B$15,☆入力!$B28,☆入力!$C28) -> 0 | G20: =☆入力!D28 -> 0 | L20: =☆入力!H28 -> 0 | P20: =☆入力!L28 -> 0 | R20: =☆入力!AA28 -> 0 | U20: =☆入力!AB28 -> 0 | Y20: =☆入力!AC28 -> 0 | AS20: +
A21: 14 | C21: =IF($C$6=☆入力!$B$15,☆入力!$B29,☆入力!$C29) -> 0 | G21: =☆入力!D29 -> 0 | L21: =☆入力!H29 -> 0 | P21: =☆入力!L29 -> 0 | R21: =☆入力!AA29 -> 0 | U21: =☆入力!AB29 -> 0 | Y21: =☆入力!AC29 -> 0
A22: 15 | C22: =IF($C$6=☆入力!$B$15,☆入力!$B30,☆入力!$C30) -> 0 | G22: =☆入力!D30 -> 0 | L22: =☆入力!H30 -> 0 | P22: =☆入力!L30 -> 0 | R22: =☆入力!AA30 -> 0 | U22: =☆入力!AB30 -> 0 | Y22: =☆入力!AC30 -> 0 | AF22: ③10年間でかかる非常灯のバッテリー交換コストの総額＝
A23: 16 | C23: =IF($C$6=☆入力!$B$15,☆入力!$B31,☆入力!$C31) -> 0 | G23: =☆入力!D31 -> 0 | L23: =☆入力!H31 -> 0 | P23: =☆入力!L31 -> 0 | R23: =☆入力!AA31 -> 0 | U23: =☆入力!AB31 -> 0 | Y23: =☆入力!AC31 -> 0
A24: 17 | C24: =IF($C$6=☆入力!$B$15,☆入力!$B32,☆入力!$C32) -> 0 | G24: =☆入力!D32 -> 0 | L24: =☆入力!H32 -> 0 | P24: =☆入力!L32 -> 0 | R24: =☆入力!AA32 -> 0 | U24: =☆入力!AB32 -> 0 | Y24: =☆入力!AC32 -> 0 | AS24: =☆入力!L12*8000*2 -> 0
A25: 18 | C25: =IF($C$6=☆入力!$B$15,☆入力!$B33,☆入力!$C33) -> 0 | G25: =☆入力!D33 -> 0 | L25: =☆入力!H33 -> 0 | P25: =☆入力!L33 -> 0 | R25: =☆入力!AA33 -> 0 | U25: =☆入力!AB33 -> 0 | Y25: =☆入力!AC33 -> 0
A26: 19 | C26: =IF($C$6=☆入力!$B$15,☆入力!$B34,☆入力!$C34) -> 0 | G26: =☆入力!D34 -> 0 | L26: =☆入力!H34 -> 0 | P26: =☆入力!L34 -> 0 | R26: =☆入力!AA34 -> 0 | U26: =☆入力!AB34 -> 0 | Y26: =☆入力!AC34 -> 0 | AG26: 計算式：非常照明の総数 | AO26: =☆入力!L12 -> 0 | AR26: ×8,000円（※4）×2回（※5）
A27: 20 | C27: =IF($C$6=☆入力!$B$15,☆入力!$B35,☆入力!$C35) -> 0 | G27: =☆入力!D35 -> 0 | L27: =☆入力!H35 -> 0 | P27: =☆入力!L35 -> 0 | R27: =☆入力!AA35 -> 0 | U27: =☆入力!AB35 -> 0 | Y27: =☆入力!AC35 -> 0
A28: 21 | C28: =IF($C$6=☆入力!$B$15,☆入力!$B36,☆入力!$C36) -> 0 | G28: =☆入力!D36 -> 0 | L28: =☆入力!H36 -> 0 | P28: =☆入力!L36 -> 0 | R28: =☆入力!AA36 -> 0 | U28: =☆入力!AB36 -> 0 | Y28: =☆入力!AC36 -> 0 | AG28: (※4)非常灯のバッテリー交換費用⇒8,000円で計算(管理会社に委託している場合の平均)
A29: 22 | C29: =IF($C$6=☆入力!$B$15,☆入力!$B37,☆入力!$C37) -> 0 | G29: =☆入力!D37 -> 0 | L29: =☆入力!H37 -> 0 | P29: =☆入力!L37 -> 0 | R29: =☆入力!AA37 -> 0 | U29: =☆入力!AB37 -> 0 | Y29: =☆入力!AC37 -> 0 | AG29: (※5)内蔵バッテリーの寿命⇒5年として10年間で2回交換することを想定して算出
A30: 23 | C30: =IF($C$6=☆入力!$B$15,☆入力!$B38,☆入力!$C38) -> 0 | G30: =☆入力!D38 -> 0 | L30: =☆入力!H38 -> 0 | P30: =☆入力!L38 -> 0 | R30: =☆入力!AA38 -> 0 | U30: =☆入力!AB38 -> 0 | Y30: =☆入力!AC38 -> 0
A31: 24 | C31: =IF($C$6=☆入力!$B$15,☆入力!$B39,☆入力!$C39) -> 0 | G31: =☆入力!D39 -> 0 | L31: =☆入力!H39 -> 0 | P31: =☆入力!L39 -> 0 | R31: =☆入力!AA39 -> 0 | U31: =☆入力!AB39 -> 0 | Y31: =☆入力!AC39 -> 0
